Workbook
Name √: "SQRT"
Name π: PI()
Name 계획년도: [1]표지!$A$2
Name 관경: #REF!
Name 관경: #REF!
Name 관경: #REF!
Name 굴착길이: #REF!
Name 굴착길이: #REF!
Name 굴착길이: #REF!
Name 단가표: [1]단가표!$A$7:$U$7
Name 매설심도: #REF!
Name 매설심도: #REF!
Name 매설심도: #REF!
Name 복구편측여유: #REF!
Name 복구편측여유: #REF!
Name 복구편측여유: #REF!
Name 비파괴검사매수: #REF!
Name 비파괴검사매수: #REF!
Name 비파괴검사매수: #REF!
Name 수요자부담분: [2]관로종합명세!$H$5
Name 야간할증율: 4%
Name 율: 100%
Name 이: [3]단가표!$A$7:$U$7
Name 이사람: [3]단가표!$A$7:$U$7
Name 이중관관경: #REF!
Name 이중관관경: #REF!
Name 이중관관경: #REF!
Name 이중관길이: #REF!
Name 이중관길이: #REF!
Name 이중관길이: #REF!
Name 인상율: 10%
Name 자재Rray1: #REF!
Name 자재Rray1: #REF!
Name 자재Rray1: #REF!
Name 자재Rray2: #REF!
Name 자재Rray2: #REF!
Name 자재Rray2: #REF!
Name 자재관경1: #REF!
Name 자재관경1: #REF!
Name 자재관경1: #REF!
Name 자재관경2: #REF!
Name 자재관경2: #REF!
Name 자재관경2: #REF!
Name 자재시트1: #REF!
Name 자재시트1: #REF!
Name 자재시트1: #REF!
Name 자재시트2: #REF!
Name 자재시트2: #REF!
Name 자재시트2: #REF!
Name 자재용접1: #REF!
Name 자재용접1: #REF!
Name 자재용접1: #REF!
Name 자재용접2: #REF!
Name 자재용접2: #REF!
Name 자재용접2: #REF!
Name 자재융착1: #REF!
Name 자재융착1: #REF!
Name 자재융착1: #REF!
Name 자재융착2: #REF!
Name 자재융착2: #REF!

Sheet 이월분
B1: 본부투자승인 공공택지 이월 현황
A3: 구분 | B3: 승인 차수 | C3: 구간번호 | D3: 공 사 명 | E3: 본부투자 승인 내역 | G3: 이월누계현황 | I3: 금년투자(2023년) | K3: 이 월 현 황 | M3: 비고
E4: 길이(m) | F4: 금액(원) | G4: 길이(m) | H4: 금액(원) | I4: 길이(m) | J4: 금액(원) | K4: 길이(m) | L4: 금액(원)
A5: 본부투자이월구간 | I5: =E5-K5 -> 0 | J5: =F5-L5 -> 0
I6: =E6-K6 -> 0 | J6: =F6-L6 -> 0
I7: =E7-K7 -> 0 | J7: =F7-L7 -> 0
B10: 소 계 | E10: =SUM(E5:E9) -> 0 | F10: =SUM(F5:F9) -> 0 | G10: =SUM(G5:G9) -> 0 | H10: =SUM(H5:H9) -> 0 | I10: =SUM(I5:I9) -> 0 | J10: =SUM(J5:J9) -> 0 | K10: =SUM(K5:K9) -> 0 | L10: =SUM(L5:L9) -> 0
A11: 금회이월구간 | I11: =E11-K11 -> 0 | J11: =F11-L11 -> 0
B16: 소 계 | E16: =SUM(E11:E15) -> 0 | F16: =SUM(F11:F15) -> 0 | G16: =SUM(G11:G15) -> 0 | H16: =SUM(H11:H15) -> 0 | I16: =SUM(I11:I15) -> 0 | J16: =SUM(J11:J15) -> 0 | K16: =SUM(K11:K15) -> 0 | L16: =SUM(L11:L15) -> 0
B17: 합 계 | E17: =SUM(E10,E16) -> 0 | F17: =SUM(F10,F16) -> 0 | G17: =SUM(G10,G16) -> 0 | H17: =SUM(H10,H16) -> 0 | I17: =SUM(I10,I16) -> 0 | J17: =SUM(J10,J16) -> 0 | K17: =SUM(K10,K16) -> 0 | L17: =SUM(L10,L16) -> 0

Sheet 취소분
B1: 2026년도 신규배관 투자승인 취소현황
A3: 구분 | B3: 승인 차수 | C3: 용도 | D3: 구간번호 | E3: 공 사 명 | F3: 관로길이 | G3: 투자금액 | H3: 시 설 분 담 금 | K3: 시설분담금 | L3: 취 소 사 유 | M3: 비고
H4: 일반 | I4: 취사전용 | J4: 수요가부담
A5: 기 존 취 소 구 간 | O5: 주택용 | P5: =F5+F19+F20+F25+F27+F28+F30 -> 0 | Q5: =G5+G19+G20+G25+G27+G28+G30 -> 0 | R5: =Q5+G88 -> 0
O17: 업무용 | P17: =F17 -> 0 | Q17: =G17 -> 0 | R17: =Q17+G86 -> 0
O18: 공동주택 | P18: =F29 -> 0 | Q18: =G29 -> 0 | R18: =Q18+G84 -> 0
O19: 투자재원 | P19: =F21+F22+F23+F24+F26 -> 0 | Q19: =G21+G22+G23+G24+G26 -> 0 | R19: =Q19+G89 -> 0
O20: ROE | P20: =F18 -> 0 | Q20: =G18 -> 0 | R20: =Q20+G90 -> 0
O21: 공공택지 | R21: =G82 -> 0
O22: 산업용 | R22: =G85 -> 0
O23: 영업용 | R23: =G87 -> 0
P24: =SUM(P5:P23) -> 0 | Q24: =SUM(Q5:Q23) -> 0 | R24: =SUM(R5:R23) -> 0
B81: 소 계 | E81: =COUNTA(B5:B80)&" 건" -> 0 건 | F81: =SUM(F5:F80) -> 0 | G81: =SUM(G5:G80) -> 0 | H81: =SUM(H5:H80) -> 0 | I81: =SUM(I5:I80) -> 0 | J81: =SUM(J5:J80) -> 0 | K81: =SUM(K5:K80) -> 0
A82: 금 회 취 소 | O82: ---> 다음회차 작업시 금회 취소분은 기존 취소로 이동복사 할 것.
P84: 559440000
P85: -160648
P86: 60745 | U86: -1
P87: 2409041
P88: 14212731
P89: 15580120
P90: 203432153 | R90: =368324000+89789000+37378000+68703000+38529000+49840000+12958000 -> 665521000
P94: 254 | Q94: 138891000
B103: 소 계 | E103: =COUNTA(B82:B101)&" 건" -> 0 건 | F103: =SUM(F82:F102) -> 0 | G103: =SUM(G82:G102) -> 0 | H103: =SUM(H82:H101) -> 0 | I103: =SUM(I82:I101) -> 0 | J103: =SUM(J82:J101) -> 0 | K103: =SUM(K82:K101) -> 0
A104: 합 계 | E104: =COUNTA(B5:B80,B82:B101)&" 건" -> 0 건 | F104: =F103+F81 -> 0 | G104: =G103+G81 -> 0 | H104: =H103+H81 -> 0 | I104: =I103+I81 -> 0 | J104: =J103+J81 -> 0 | K104: =K103+K81 -> 0 | L104: =SUM(L8:L103) -> 0
P105: 665521000
P106: =G91+G92+G96+G97 -> 0
P107: =G94+G95 -> 0
Q108: 구분 | R108: 수 요 개 발 | U108: 기본계획 | V108: 합 계
R109: 취 소 | S109: 이 월 | T109: 소 계 | U109: 취 소
Q110: 금액 | R110: =G104 -> 0 | S110: =이월분!L17 -> 0 | T110: =R110+S110 -> 0 | U110: =투자현황!T27 -> 0 | V110: =U110+T110 -> 0
G112: =SUM(G82:G89) -> 0

Sheet 요약보고
A2: 2026년도 본부투자승인 현황
A4: 차수 | B4: 건 수 | C4: 길이(m) | D4: 관로투자금액 | E4: 시설투자금액 | F4: 투자재원 | G4: 이월,취소금액 | H4: 합 계 | I4: 누 계
A5: 승 인 현 황 | E5: 0 | H5: =SUM(D5,E5,F5) -> 0 | J5: 취소금액 | K5: 차수별 취소 금액 | Q5: 관로공사 발주에 따른 시공도급비 감소분
A6: 1차 | B6: 1건 | C6: 49 | D6: 67366000 | G6: =J6 -> 0 | H6: =IF(A6="","",SUM(D6:F6)-G6) -> 67366000 | I6: =H6 -> 67366000 | J6: =SUM(K6:Q6) -> 0
A7: 2차 | B7: 2건 | C7: 283 | D7: 222907000 | G7: =J7 -> 0 | H7: =IF(A7="","",SUM(D7:F7)-G7) -> 222907000 | I7: =IF(A7="","",(I6+H7)) -> 290273000 | J7: =SUM(K7:Q7) -> 0
A8: 3차 | B8: 4건 | C8: 2229 | D8: 2631473000 | G8: =J8 -> 0 | H8: =IF(A8="","",SUM(D8:F8)-G8) -> 2631473000 | I8: =IF(A8="","",(I7+H8)) -> 2921746000 | J8: =SUM(K8:Q8) -> 0
A9: 4차 | B9: 1건 | C9: 7 | D9: 19077000 | G9: =J9 -> 0 | H9: =IF(A9="","",SUM(D9:F9)-G9) -> 19077000 | I9: =IF(A9="","",(I8+H9)) -> 2940823000 | J9: =SUM(K9:Q9) -> 0
A10: 5차 | B10: 1건 | C10: 192 | D10: 439232000 | G10: =J10 -> 0 | H10: =IF(A10="","",SUM(D10:F10)-G10) -> 439232000 | I10: =IF(A10="","",(I9+H10)) -> 3380055000 | J10: =SUM(K10:Q10) -> 0
A11: 6차 | B11: 12건 | C11: 1358 | D11: 1126967000 | G11: =J11 -> 0 | H11: =IF(A11="","",SUM(D11:F11)-G11) -> 1126967000 | I11: =IF(A11="","",(I10+H11)) -> 4507022000 | J11: =SUM(K11:Q11) -> 0
A12: 7차 | B12: 1건 | C12: 116 | D12: 188979000 | G12: =J12 -> 0 | H12: =IF(A12="","",SUM(D12:F12)-G12) -> 188979000 | I12: =IF(A12="","",(I11+H12)) -> 4696001000 | J12: =SUM(K12:Q12) -> 0
A13: 8차 | B13: 10건 | C13: 588 | D13: 428872000 | G13: =J13 -> 0 | H13: =IF(A13="","",SUM(D13:F13)-G13) -> 428872000 | I13: =IF(A13="","",(I12+H13)) -> 5124873000 | J13: =SUM(K13:Q13) -> 0
A14: 9차 | B14: 2건 | C14: 59 | D14: 69443000 | G14: =J14 -> 0 | H14: =IF(A14="","",SUM(D14:F14)-G14) -> 69443000 | I14: =IF(A14="","",(I13+H14)) -> 5194316000 | J14: =SUM(K14:Q14) -> 0
A15: 10차 | B15: 6건 | C15: 291 | D15: 228501000 | G15: =J15 -> 0 | H15: =IF(A15="","",SUM(D15:F15)-G15) -> 228501000 | I15: =IF(A15="","",(I14+H15)) -> 5422817000 | J15: =SUM(K15:Q15) -> 0
A16: 11차 | B16: 5건 | C16: 262 | D16: 3169441000 | G16: =J16 -> 0 | H16: =IF(A16="","",SUM(D16:F16)-G16) -> 3169441000 | I16: =IF(A16="","",(I15+H16)) -> 8592258000 | J16: =SUM(K16:Q16) -> 0
G17: =J17 -> 0 | H17: =IF(A17="","",SUM(D17:F17)-G17) | I17: =IF(A17="","",(I16+H17)) | J17: =SUM(K17:Q17) -> 0
G18: =J18 -> 0 | H18: =IF(A18="","",SUM(D18:F18)-G18) | I18: =IF(A18="","",(I17+H18)) | J18: =SUM(K18:Q18) -> 0
G19: =J19 -> 0 | H19: =IF(A19="","",SUM(D19:F19)-G19) | I19: =IF(A19="","",(I18+H19)) | J19: =SUM(K19:Q19) -> 0
G20: =J20 -> 0 | H20: =IF(A20="","",SUM(D20:F20)-G20) | I20: =IF(A20="","",(I19+H20)) | J20: =SUM(K20:Q20) -> 0
G21: =J21 -> 0 | H21: =IF(A21="","",SUM(D21:F21)-G21) | I21: =IF(A21="","",(I20+H21)) | J21: =SUM(K21:Q21) -> 0
G22: =J22 -> 0 | H22: =IF(A22="","",SUM(D22:F22)-G22) | I22: =IF(A22="","",(I21+H22)) | J22: =SUM(K22:Q22) -> 0
H23: =IF(A23="","",SUM(D23:F23)-G23) | I23: =IF(A23="","",(I22+H23)) | J23: =SUM(K23:Q23) -> 0
H24: =IF(A24="","",SUM(D24:F24)-G24) | I24: =IF(A24="","",(I23+H24)) | J24: =SUM(K24:Q24) -> 0
H25: =IF(A25="","",SUM(D25:F25)-G25) | I25: =IF(A25="","",(I24+H25)) | J25: =SUM(K25:Q25) -> 0
H26: =IF(A26="","",SUM(D26:F26)-G26) | I26: =IF(A26="","",(I25+H26)) | J26: =SUM(K26:Q26) -> 0
H27: =IF(A27="","",SUM(D27:F27)-G27) | I27: =IF(A27="","",(I26+H27)) | J27: =SUM(K27:Q27) -> 0
H28: =IF(A28="","",SUM(D28:F28)-G28) | I28: =IF(A28="","",(I27+H28)) | J28: =SUM(K28:Q28) -> 0
H29: =IF(A29="","",SUM(D29:F29)-G29) | I29: =IF(A29="","",(I28+H29)) | J29: =SUM(K29:Q29) -> 0
H30: =IF(A30="","",SUM(D30:F30)-G30) | I30: =IF(A30="","",(I29+H30)) | J30: =SUM(K30:Q30) -> 0
H31: =IF(A31="","",SUM(D31:F31)-G31) | I31: =IF(A31="","",(I30+H31)) | J31: =SUM(K31:Q31) -> 0
H32: =IF(A32="","",SUM(D32:F32)-G32) | I32: =IF(A32="","",(I31+H32)) | J32: =SUM(K32:Q32) -> 0
H33: =IF(A33="","",SUM(D33:F33)-G33) | I33: =IF(A33="","",(I32+H33)) | J33: =SUM(K33:Q33) -> 0
H34: =IF(A34="","",SUM(D34:F34)-G34) | I34: =IF(A34="","",(I33+H34)) | J34: =SUM(K34:Q34) -> 0
... H44: =IF(A44="","",SUM(D44:F44)-G44) | I44: =IF(A44="","",(I43+H44)) | J44: =SUM(K44:Q44) -> 0
H45: =IF(A45="","",SUM(D45:F45)-G45) | I45: =IF(A45="","",(I44+H45))
I46: =IF(A46="","",(I45+H46))
I47: =IF(A47="","",(I46+H47))
I48: =IF(A48="","",(I47+H48))
I49: =IF(A49="","",(I48+H49))
I50: =IF(A50="","",(I49+H50))
I51: =IF(A51="","",(I50+H51))
...

Sheet 투자현황
AB6: 0 | AG6: [금액단위:천원]
A7: 구 분 | C7: 2025년 투자 실적 | F7: 2026년 당초 투자한도액 | H7: 2024년 신규투자 잔여분 | I7: 2026년 사업계획 투자한도액 | L7: 2026년 본부투자 승인내역 | O7: 금회 신청 내역(11차) | R7: 2026년 본부투자 이월 및 취소분 | U7: 2025년 본부투자 누계 | X7: 2026년 본부투자 누계 | AB7: 투자한도 잔 액 | AC7: 시설분담금 | AF7: 시설분담금 | AG7: 승인비율
C8: 규모(m) | D8: 금액 | E8: 구성비 | F8: 규모(m) | G8: 금액 | I8: 규모(m) | J8: 금액 | K8: 구성비 | L8: 전수 | M8: 규모(m) | N8: 금액 | O8: 전수 | P8: 규모(m) | Q8: 금액 | R8: 전수 | S8: 규모(m) | T8: 금액 | U8: 전수 | V8: 규모(m) | W8: 금액 | X8: 전수 | Y8: 규모(m) | Z8: 금액 | AA8: 구성비 | AC8: 일반 | AD8: 취사전용 | AE8: 수요가부담 | AJ8: 전수 | AK8: 규모 | AL8: 금액
A9: 수요개발 | B9: 공공택지 | C9: 3653 | D9: 2510347000 | E9: =D9/$D$28 -> 0.10826891 | F9: 1556 | G9: 1.0554306e+09 | I9: 1556 | J9: 1.0554306e+09 | K9: =J9/$J$28 -> 0.070994232 | L9: 2542 | M9: 172 | N9: 153713000 | U9: =L9+O9 -> 2542 | V9: =M9+P9 -> 172 | W9: =N9+Q9 -> 153713000 | X9: =L9+O9-R9 -> 2542 | Y9: =M9+P9-S9 -> 172 | Z9: =N9+Q9-T9 -> 153713000 | AA9: =Z9/$Z$28 -> 0.01788971 | AB9: =J9-Z9 -> 9.0171756e+08 | AG9: =IFERROR(Z9/J9,"") -> 0.14564009 | AI9: 공공택지 | AJ9: =[5]용도별분석!AH9 -> 0 | AK9: =[5]용도별분석!E9 -> 0 | AL9: =[5]용도별분석!H9 -> 0
B10: 공동주택 | C10: 921 | D10: 1397023000 | E10: =D10/$D$28 -> 0.060252291 | F10: 906 | G10: 8.5119675e+08 | I10: 906 | J10: 8.5119675e+08 | K10: =J10/$J$28 -> 0.057256311 | L10: 5425 | M10: 236 | N10: 376532000 | U10: =L10+O10 -> 5425 | V10: =M10+P10 -> 236 | W10: =N10+Q10 -> 376532000 | X10: =L10+O10-R10 -> 5425 | Y10: =M10+P10-S10 -> 236 | Z10: =N10+Q10-T10 -> 376532000 | AA10: =Z10/$Z$28 -> 0.043822241 | AB10: =J10-Z10 -> 4.7466475e+08 | AG10: =IFERROR(Z10/J10,"") -> 0.44235601 | AI10: 공동주택 | AJ10: =[5]용도별분석!AH11 -> 278 | AK10: =[5]용도별분석!E11 -> 142 | AL10: =[5]용도별분석!H11 -> 132410000
B11: 산업용 | C11: 595 | D11: 450233000 | E11: =D11/$D$28 -> 0.019418127 | F11: 325 | G11: 2.8756827e+08 | I11: 325 | J11: 2.8756827e+08 | K11: =J11/$J$28 -> 0.01934347 | L11: 0 | M11: 0 | N11: 0 | U11: =L11+O11 -> 0 | V11: =M11+P11 -> 0 | W11: =N11+Q11 -> 0 | X11: =L11+O11-R11 -> 0 | Y11: =M11+P11-S11 -> 0 | Z11: =N11+Q11-T11 -> 0 | AA11: =Z11/$Z$28 -> 0 | AB11: =J11-Z11 -> 2.8756827e+08 | AG11: =IFERROR(Z11/J11,"") -> 0 | AI11: 산업용 | AJ11: =[5]용도별분석!AH14 -> 0 | AK11: =[5]용도별분석!E14 -> 0 | AL11: =[5]용도별분석!H14 -> 0
B12: 업무용 | C12: 514 | D12: 651328000 | E12: =D12/$D$28 -> 0.028091166 | F12: 498 | G12: 4.3942951e+08 | I12: 498 | J12: 4.3942951e+08 | K12: =J12/$J$28 -> 0.029558516 | L12: 10 | M12: 155 | N12: 128275000 | U12: =L12+O12 -> 10 | V12: =M12+P12 -> 155 | W12: =N12+Q12 -> 128275000 | X12: =L12+O12-R12 -> 10 | Y12: =M12+P12-S12 -> 155 | Z12: =N12+Q12-T12 -> 128275000 | AA12: =Z12/$Z$28 -> 0.014929137 | AB12: =J12-Z12 -> 3.1115451e+08 | AG12: =IFERROR(Z12/J12,"") -> 0.29191258 | AI12: 업무용 | AJ12: =[5]용도별분석!AH17 -> 5 | AK12: =[5]용도별분석!E17 -> 141 | AL12: =[5]용도별분석!H17 -> 90497000
B13: 영업용 | C13: 3 | D13: 18447000 | E13: =D13/$D$28 -> 0.0007956018 | F13: 275 | G13: 1.8295611e+08 | I13: 275 | J13: 1.8295611e+08 | K13: =J13/$J$28 -> 0.012306664 | L13: 8 | M13: 76 | N13: 116322000 | U13: =L13+O13 -> 8 | V13: =M13+P13 -> 76 | W13: =N13+Q13 -> 116322000 | X13: =L13+O13-R13 -> 8 | Y13: =M13+P13-S13 -> 76 | Z13: =N13+Q13-T13 -> 116322000 | AA13: =Z13/$Z$28 -> 0.013538001 | AB13: =J13-Z13 -> 66634113 | AG13: =IFERROR(Z13/J13,"") -> 0.63579182 | AI13: 영업용 | AJ13: =[5]용도별분석!AH29 -> 0 | AK13: =[5]용도별분석!E29 -> 0 | AL13: =[5]용도별분석!H29 -> 0
B14: 연료전지용 | C14: 0 | D14: 0 | E14: =D14/$D$28 -> 0 | F14: 735 | G14: 6.1043548e+08 | I14: 735 | J14: 6.1043548e+08 | K14: =J14/$J$28 -> 0.041061345 | L14: 1 | M14: 470 | N14: 474456000 | U14: =L14+O14 -> 1 | V14: =M14+P14 -> 470 | W14: =N14+Q14 -> 474456000 | X14: =L14+O14-R14 -> 1 | Y14: =M14+P14-S14 -> 470 | Z14: =N14+Q14-T14 -> 474456000 | AA14: =Z14/$Z$28 -> 0.055219012 | AB14: =J14-Z14 -> 1.3597948e+08 | AG14: =IFERROR(Z14/J14,"") -> 0.77724185 | AI14: 연료전지용 | AJ14: =[5]용도별분석!AH20 -> 0 | AK14: =[5]용도별분석!E20 -> 0 | AL14: =[5]용도별분석!H20 -> 0
B15: 주택용 | C15: 6377 | D15: 4653481000 | E15: =D15/$D$28 -> 0.20070027 | K15: =J15/$J$28 -> 0 | L15: 28 | M15: 16 | N15: 20205000 | U15: =L15+O15 -> 28 | V15: =M15+P15 -> 16 | W15: =N15+Q15 -> 20205000 | X15: =L15+O15-R15 -> 28 | Y15: =M15+P15-S15 -> 16 | Z15: =N15+Q15-T15 -> 20205000 | AA15: =Z15/$Z$28 -> 0.0023515355 | AB15: =J15-Z15 -> -20205000 | AG15: =IFERROR(Z15/J15,"") | AI15: 주택용 | AJ15: =[5]용도별분석!AH32 -> 0 | AK15: =[5]용도별분석!E32 -> 0 | AL15: =[5]용도별분석!H32 -> 0
B16: 소 계 | C16: 15603 | D16: 10662598000 | E16: =SUM(E9:E15) -> 0.41752637 | F16: =SUM(F9:F15) -> 4295 | G16: =SUM(G9:G15) -> 3.4270167e+09 | H16: =SUM(H9:H15) -> 0 | I16: =SUM(I9:I15) -> 4295 | J16: =SUM(J9:J15) -> 3.4270167e+09 | K16: =SUM(K9:K15) -> 0.23052054 | L16: 8014 | M16: 1125 | N16: 1269503000 | R16: =SUM(R9:R15) -> 0 | S16: =SUM(S9:S15) -> 0 | T16: =SUM(T9:T15) -> 0 | U16: =SUM(U9:U15) -> 8014 | V16: =SUM(V9:V15) -> 1125 | W16: =SUM(W9:W15) -> 1269503000 | X16: =SUM(X9:X15) -> 8014 | Y16: =SUM(Y9:Y15) -> 1125 | Z16: =SUM(Z9:Z15) -> 1269503000 | AA16: =Z16/$Z$28 -> 0.14774964 | AB16: =SUM(AB9:AB15) -> 2.1575137e+09 | AG16: =IFERROR(Z16/J16,"") -> 0.37043969 | AI16: 소계 | AJ16: =SUM(AJ9:AJ15) -> 283 | AK16: =SUM(AK9:AK15) -> 283 | AL16: =SUM(AL9:AL15) -> 222907000
A17: 배관투자재원 | C17: 0 | D17: 0 | E17: =D17/$D$28 -> 0 | K17: =J17/J28 -> 0 | L17: 0 | M17: 0 | N17: 0 | U17: =L17+O17 -> 0 | V17: =M17+P17 -> 0 | W17: =N17+Q17 -> 0 | X17: =L17+O17-R17 -> 0 | Y17: =M17+P17-S17 -> 0 | Z17: =N17+Q17-T17 -> 0 | AA17: =Z17/$Z$28 -> 0 | AB17: =J17-Z17 -> 0 | AG17: =IFERROR(Z17/J17,"") | AI17: =Y16-Y9+S16 -> 953
A18: 투자보수율가산 | C18: 3051 | D18: 1879144000 | E18: =D18/$D$28 -> 0.081045718 | F18: 3004 | G18: 1.695844e+09 | I18: 3004 | J18: 1.695844e+09 | K18: =J18/J28 -> 0.11407207 | L18: 0 | M18: 1510 | N18: 893630000 | U18: =L18+O18 -> 0 | V18: =M18+P18 -> 1510 | W18: =N18+Q18 -> 893630000 | X18: =L18+O18-R18 -> 0 | Y18: =M18+P18-S18 -> 1510 | Z18: =N18+Q18-T18 -> 893630000 | AA18: =Z18/$Z$28 -> 0.10400409 | AB18: =J18-Z18 -> 8.0221401e+08 | AG18: =IFERROR(Z18/J18,"") -> 0.52695295 | AI18: =Z16-Z9+T16 -> 1115790000
A19: 합 계 | C19: 19948 | D19: 14431426000 | E19: =SUM(E16+SUM(E17:E18)) -> 0.49857208 | F19: =F16+F17+F18 -> 7299 | G19: =G16+G17+G18 -> 5.1228607e+09 | H19: =SUM(H16+SUM(H17:H18)) -> 0 | I19: =I16+I17+I18 -> 7299 | J19: =J16+J17+J18 -> 5.1228607e+09 | K19: =SUM(K16+SUM(K17:K18)) -> 0.3445926 | L19: 8014 | M19: 2635 | N19: 2163133000 | R19: =SUM(R16:R18) -> 0 | S19: =SUM(S16:S18) -> 0 | T19: =SUM(T16:T18) -> 0 | U19: =SUM(U16:U18) -> 8014 | V19: =SUM(V16:V18) -> 2635 | W19: =SUM(W16:W18) -> 2163133000 | X19: =SUM(X16:X18) -> 8014 | Y19: =SUM(Y16:Y18) -> 2635 | ... AB19: =SUM(AB16:AB18) -> 2.9597277e+09 | AC19: =AC16+#REF!+AC17 -> #REF! | AD19: =AD16+#REF!+AD17 -> #REF! | AE19: =AE16+#REF!+AE17 -> #REF! | AF19: =AF16+#REF!+AF17 -> #REF! | AG19: =IFERROR(Z19/J19,"") -> 0.42225099 | AI19: 소계 | AJ19: =AJ16 -> 283 | AK19: =AK16 -> 283 | AL19: =AL16 -> 222907000
A20: 기본계획 | B20: 계획배관 | C20: 2100 | D20: 2809538000 | E20: =D20/$D$28 -> 0.12117274 | F20: 2828 | G20: 2.031952e+09 | I20: 2828 | J20: 2.031952e+09 | K20: =J20/$J$28 -> 0.13668059 | M20: 2345 | N20: 1083876000 | P20: 23 | Q20: 93728000 | U20: =L20+O20 -> 0 | V20: =M20+P20 -> 2368 | W20: =N20+Q20 -> 1177604000 | Y20: =M20+P20-S20 -> 2368 | Z20: =N20+Q20-T20 -> 1177604000 | AA20: =Z20/$Z$28 -> 0.13705408 | AB20: =J20-Z20 -> 8.5434801e+08 | AF20: =SUM(AC20:AE20) -> 0 | AG20: =IFERROR(Z20/J20,"") -> 0.57954321
B21: Loop | C21: 272 | D21: 228087000 | E21: =D21/$D$28 -> 0.0098371783 | F21: 749 | G21: 6.2698784e+08 | I21: 749 | J21: 6.2698784e+08 | K21: =J21/$J$28 -> 0.04217475 | M21: 0 | N21: 0 | U21: =L21+O21 -> 0 | V21: =M21+P21 -> 0 | W21: =N21+Q21 -> 0 | Y21: =M21+P21-S21 -> 0 | Z21: =N21+Q21-T21 -> 0 | AA21: =Z21/$Z$28 -> 0 | AB21: =J21-Z21 -> 6.2698784e+08 | AF21: =SUM(AC21:AE21) -> 0 | AG21: =IFERROR(Z21/J21,"") -> 0
B22: 이설배관 | C22: 40 | D22: 22356000 | E22: =D22/$D$28 -> 0.0009641933 | F22: 624 | G22: 7.664525e+08 | I22: 624 | J22: 7.664525e+08 | K22: =J22/$J$28 -> 0.051555933 | M22: 192 | N22: 439232000 | P22: 239 | Q22: 693576000 | U22: =L22+O22 -> 0 | V22: =M22+P22 -> 431 | W22: =N22+Q22 -> 1132808000 | Y22: =M22+P22-S22 -> 431 | Z22: =N22+Q22-T22 -> 1132808000 | AA22: =Z22/$Z$28 -> 0.13184055 | AB22: =J22-Z22 -> -3.663555e+08 | AF22: =SUM(AC22:AE22) -> 0 | AG22: =IFERROR(Z22/J22,"") -> 1.4779885 | AJ22: =Y16-S16-AJ21 -> 1125 | AK22: =Z16-T16-AK21 -> 1269503000
B23: 지역 정압기 | C23: 0 | D23: 750428000 | E23: =D23/$D$28 -> 0.032365256 | F23: 3 | G23: 3.3804502e+08 | I23: 3 | J23: 3.3804502e+08 | K23: =J23/$J$28 -> 0.022738821 | M23: 0 | N23: 109867000 | Q23: 205427000 | U23: =L23+O23 -> 0 | W23: =N23+Q23 -> 315294000 | Y23: =M23+P23 -> 0 | Z23: =N23+Q23-T23 -> 315294000 | AA23: =Z23/$Z$28 -> 0.036695127 | AB23: =J23-Z23 -> 22751023 | AF23: =SUM(AC23:AE23) -> 0 | AG23: =IFERROR(Z23/J23,"") -> 0.93269825 | AJ23: =Y16+S16-AJ21 -> 1125 | AK23: =Z16+T16-AK21 -> 1269503000
B24: 인입배관 | D24: 3522977000 | E24: =D24/$D$28 -> 0.15194269 | F24: 856.647 | G24: 3.230129e+09 | I24: 856.647 | J24: 3.230129e+09 | K24: =J24/$J$28 -> 0.21727676 | N24: 1076709000 | Q24: 1076710000 | W24: =N24+Q24 -> 2153419000 | Z24: =N24+Q24-T24 -> 2153419000 | AA24: =Z24/$Z$28 -> 0.25062318 | AB24: =J24-Z24 -> 1.07671e+09 | AF24: =SUM(AC24:AE24) -> 0 | AG24: =IFERROR(Z24/J24,"") -> 0.66666656 | AJ24: =Z19/J19 -> 0.42225099 | AK24: 수요개발
B25: 공급시설물 개선 | D25: 1421410000 | E25: =D25/$D$28 -> 0.06130408 | F25: 95 | G25: 2.7499997e+09 | I25: 95 | J25: 2.7499997e+09 | K25: =J25/$J$28 -> 0.18498054 | N25: 550000000 | Q25: 1100000000 | W25: =N25+Q25 -> 1650000000 | Z25: =N25+Q25-T25 -> 1650000000 | AA25: =Z25/$Z$28 -> 0.19203334 | AB25: =J25-Z25 -> 1.0999997e+09 | AG25: =IFERROR(Z25/J25,"") -> 0.60000006 | AJ25: =Z27/J27 -> 0.65983285 | AK25: 기본계획
D26: 0 | H26: =G26/$J$28 -> 0 | K26: =J26/$J$28 -> 0 | N26: 0 | W26: =N26+Q26 -> 0 | Z26: =N26+Q26-T26 -> 0 | AA26: =Z26/$Z$28 -> 0 | AB26: =J26-Z26 -> 0 | AG26: =IFERROR(Z26/J26,"") | AJ26: =Z28/J28 -> 0.5779639 | AK26: 전체
A27: 소 계 | C27: =SUM(C20:C22) -> 2412 | D27: =SUM(D20:D26) -> 8754796000 | E27: =SUM(E20:E26) -> 0.37758614 | F27: =SUM(F20:F22) -> 4201 | G27: =SUM(G20:G26) -> 9.7435661e+09 | H27: =SUM(H20:H26) -> 0 | I27: =SUM(I20:I22) -> 4201 | J27: =SUM(J20:J26) -> 9.7435661e+09 | K27: =SUM(K20:K26) -> 0.6554074 | L27: 0 | M27: 2537 | N27: 3259684000 | O27: =SUM(O20:O24) -> 0 | P27: =SUM(P20:P24) -> 262 | Q27: =SUM(Q20:Q26) -> 3169441000 | R27: =SUM(R20:R24) -> 0 | S27: =SUM(S20:S24) -> 0 | T27: =SUM(T20:T26) -> 0 | U27: =SUM(U20:U24) -> 0 | V27: =SUM(V20:V22) -> 2799 | W27: =SUM(W20:W26) -> 6429125000 | X27: =SUM(X20:X24) -> 0 | Y27: =SUM(Y20:Y22) -> 2799 | Z27: =SUM(Z20:Z26) -> 6429125000 | AA27: =SUM(AA20:AA26) -> 0.74824627 | AB27: =SUM(AB20:AB26) -> 3.3144411e+09 | AC27: =SUM(AC17:AC22) -> #REF! | AD27: =SUM(AD17:AD22) -> #REF! | AE27: =SUM(AE17:AE22) -> #REF! | AF27: =SUM(AF17:AF22) -> #REF! | AG27: =IFERROR(Z27/J27,"") -> 0.65983285
A28: 총 합 계 | C28: =C19+C27 -> 22360 | D28: =SUM(D19,D27) -> 23186222000 | E28: =SUM(E19,E27) -> 0.87615822 | F28: =F27+F19 -> 11500 | G28: =G27+G19 -> 1.4866427e+10 | H28: =H27+H19 -> 0 | I28: =I27+I19 -> 11500 | J28: =J27+J19 -> 1.4866427e+10 | K28: =K27+K19 -> 1 | L28: =L27+L19 -> 8014 | M28: =M27+M19 -> 5172 | ... Z28: =Z27+Z19 -> 8592258000 | AA28: =SUM(AA19,AA27) -> 1 | AB28: =ROUND(SUM(AB19,AB27),0) -> 6274168837 | AC28: =SUM(AC22+SUM(AC23:AC27)) -> #REF! | AD28: =SUM(AD22+SUM(AD23:AD27)) -> #REF! | AE28: =SUM(AE22+SUM(AE23:AE27)) -> #REF! | AF28: =SUM(AF22+SUM(AF23:AF27)) -> #REF! | AG28: =IFERROR(Z28/J28,"") -> 0.5779639 | AJ28: =Z28 -> 8592258000
Z30: =Z28=요약보고!I62 -> TRUE | AB30: =ROUND((J28-N28-Q28+T28),0) -> 6274168837
AB31: =AB28-AB30 -> 0
AB32: =Z28/J28 -> 0.5779639 | AG32: 전체
AB33: =Z19/J19 -> 0.42225099 | AG33: 수요개발
AB34: =Z27/J27 -> 0.65983285 | AG34: 기본계획 | AK34: 구분 | AL34: 투자누계(%)
AK35: 수요개발투자 | AL35: =AB33 -> 0.42225099
AK36: 기본계획투자 | AL36: =AB34 -> 0.65983285
AK37: 전체 투자 | AL37: =AB32 -> 0.5779639
AH39: =10908669800-10741377000 -> 167292800
AH40: =818047800-650755000 -> 167292800
AH41: =215530800-48238000 -> 167292800
