Workbook
Name √: "SQRT"
Name π: PI()
Name 계획년도: [1]표지!$A$2
Name 관경: #REF!
Name 관경: #REF!
Name 관경: #REF!
Name 관경: #REF!
Name 관경: #REF!
Name 관경: #REF!
Name 관경: #REF!
Name 관경: #REF!
Name 굴착길이: #REF!
Name 굴착길이: #REF!
Name 굴착길이: #REF!
Name 굴착길이: #REF!
Name 굴착길이: #REF!
Name 굴착길이: #REF!
Name 굴착길이: #REF!
Name 굴착길이: #REF!
Name 기본: 기본데이타!$F$10:$BV$103
Name 단가표: [1]단가표!$A$7:$U$7
Name 매설심도: #REF!
Name 매설심도: #REF!
Name 매설심도: #REF!
Name 매설심도: #REF!
Name 매설심도: #REF!
Name 매설심도: #REF!
Name 매설심도: #REF!
Name 매설심도: #REF!
Name 복구편측여유: #REF!
Name 복구편측여유: #REF!
Name 복구편측여유: #REF!
Name 복구편측여유: #REF!
Name 복구편측여유: #REF!
Name 복구편측여유: #REF!
Name 복구편측여유: #REF!
Name 복구편측여유: #REF!
Name 비파괴검사매수: #REF!
Name 비파괴검사매수: #REF!
Name 비파괴검사매수: #REF!
Name 비파괴검사매수: #REF!
Name 비파괴검사매수: #REF!
Name 비파괴검사매수: #REF!
Name 비파괴검사매수: #REF!
Name 비파괴검사매수: #REF!
Name 수요자부담분: [2]관로종합명세!$H$5
Name 야간할증율: 4%
Name 율: 100%
Name 이: [3]단가표!$A$7:$U$7
Name 이사람: [3]단가표!$A$7:$U$7
Name 이중관관경: #REF!
Name 이중관관경: #REF!
Name 이중관관경: #REF!
Name 이중관관경: #REF!
Name 이중관관경: #REF!
Name 이중관관경: #REF!
Name 이중관관경: #REF!
Name 이중관관경: #REF!
Name 이중관길이: #REF!
Name 이중관길이: #REF!

Sheet 이월분
B1: 본부투자승인 공공택지 이월 현황
A3: 구분 | B3: 승인 차수 | C3: 구간번호 | D3: 공 사 명 | E3: 본부투자 승인 내역 | G3: 이월누계현황 | I3: 금년투자(2023년) | K3: 이 월 현 황 | M3: 비고
E4: 길이(m) | F4: 금액(원) | G4: 길이(m) | H4: 금액(원) | I4: 길이(m) | J4: 금액(원) | K4: 길이(m) | L4: 금액(원)
A5: 본부투자이월구간 | I5: =E5-K5 -> 0 | J5: =F5-L5 -> 0
I6: =E6-K6 -> 0 | J6: =F6-L6 -> 0
I7: =E7-K7 -> 0 | J7: =F7-L7 -> 0
B10: 소 계 | E10: =SUM(E5:E9) -> 0 | F10: =SUM(F5:F9) -> 0 | G10: =SUM(G5:G9) -> 0 | H10: =SUM(H5:H9) -> 0 | I10: =SUM(I5:I9) -> 0 | J10: =SUM(J5:J9) -> 0 | K10: =SUM(K5:K9) -> 0 | L10: =SUM(L5:L9) -> 0
A11: 금회이월구간 | I11: =E11-K11 -> 0 | J11: =F11-L11 -> 0
B16: 소 계 | E16: =SUM(E11:E15) -> 0 | F16: =SUM(F11:F15) -> 0 | G16: =SUM(G11:G15) -> 0 | H16: =SUM(H11:H15) -> 0 | I16: =SUM(I11:I15) -> 0 | J16: =SUM(J11:J15) -> 0 | K16: =SUM(K11:K15) -> 0 | L16: =SUM(L11:L15) -> 0
B17: 합 계 | E17: =SUM(E10,E16) -> 0 | F17: =SUM(F10,F16) -> 0 | G17: =SUM(G10,G16) -> 0 | H17: =SUM(H10,H16) -> 0 | I17: =SUM(I10,I16) -> 0 | J17: =SUM(J10,J16) -> 0 | K17: =SUM(K10,K16) -> 0 | L17: =SUM(L10,L16) -> 0

Sheet 취소분
B1: 2026년도 신규배관 투자승인 취소현황
A3: 구분 | B3: 승인 차수 | C3: 용도 | D3: 구간번호 | E3: 공 사 명 | F3: 관로길이 | G3: 투자금액 | H3: 시 설 분 담 금 | K3: 시설분담금 | L3: 취 소 사 유 | M3: 비고
H4: 일반 | I4: 취사전용 | J4: 수요가부담
A5: 기 존 취 소 구 간 | O5: 주택용 | P5: =F5+F19+F20+F25+F27+F28+F30 -> 0 | Q5: =G5+G19+G20+G25+G27+G28+G30 -> 0 | R5: =Q5+G88 -> 0
O17: 업무용 | P17: =F17 -> 0 | Q17: =G17 -> 0 | R17: =Q17+G86 -> 0
O18: 공동주택 | P18: =F29 -> 0 | Q18: =G29 -> 0 | R18: =Q18+G84 -> 0
O19: 투자재원 | P19: =F21+F22+F23+F24+F26 -> 0 | Q19: =G21+G22+G23+G24+G26 -> 0 | R19: =Q19+G89 -> 0
O20: ROE | P20: =F18 -> 0 | Q20: =G18 -> 0 | R20: =Q20+G90 -> 0
O21: 공공택지 | R21: =G82 -> 0
O22: 산업용 | R22: =G85 -> 0
O23: 영업용 | R23: =G87 -> 0
P24: =SUM(P5:P23) -> 0 | Q24: =SUM(Q5:Q23) -> 0 | R24: =SUM(R5:R23) -> 0
B81: 소 계 | E81: =COUNTA(B5:B80)&" 건" -> 0 건 | F81: =SUM(F5:F80) -> 0 | G81: =SUM(G5:G80) -> 0 | H81: =SUM(H5:H80) -> 0 | I81: =SUM(I5:I80) -> 0 | J81: =SUM(J5:J80) -> 0 | K81: =SUM(K5:K80) -> 0
A82: 금 회 취 소 | O82: ---> 다음회차 작업시 금회 취소분은 기존 취소로 이동복사 할 것.
P84: 559440000
P85: -160648
P86: 60745 | U86: -1
P87: 2409041
P88: 14212731
P89: 15580120
P90: 203432153 | R90: =368324000+89789000+37378000+68703000+38529000+49840000+12958000 -> 665521000
P94: 254 | Q94: 138891000
B103: 소 계 | E103: =COUNTA(B82:B101)&" 건" -> 0 건 | F103: =SUM(F82:F102) -> 0 | G103: =SUM(G82:G102) -> 0 | H103: =SUM(H82:H101) -> 0 | I103: =SUM(I82:I101) -> 0 | J103: =SUM(J82:J101) -> 0 | K103: =SUM(K82:K101) -> 0
A104: 합 계 | E104: =COUNTA(B5:B80,B82:B101)&" 건" -> 0 건 | F104: =F103+F81 -> 0 | G104: =G103+G81 -> 0 | H104: =H103+H81 -> 0 | I104: =I103+I81 -> 0 | J104: =J103+J81 -> 0 | K104: =K103+K81 -> 0 | L104: =SUM(L8:L103) -> 0
P105: 665521000
P106: =G91+G92+G96+G97 -> 0
P107: =G94+G95 -> 0
Q108: 구분 | R108: 수 요 개 발 | U108: 기본계획 | V108: 합 계
R109: 취 소 | S109: 이 월 | T109: 소 계 | U109: 취 소
Q110: 금액 | R110: =G104 -> 0 | S110: =이월분!L17 -> 0 | T110: =R110+S110 -> 0 | U110: =투자현황!T27 -> 0 | V110: =U110+T110 -> 0
G112: =SUM(G82:G89) -> 0

Sheet 요약보고
A2: 2026년도 본부투자승인 현황
A4: 차수 | B4: 건 수 | C4: 길이(m) | D4: 관로투자금액 | E4: 시설투자금액 | F4: 투자재원 | G4: 이월,취소금액 | H4: 합 계 | I4: 누 계
A5: 승 인 현 황 | E5: 0 | H5: =SUM(D5,E5,F5) -> 0 | J5: 취소금액 | K5: 차수별 취소 금액 | Q5: 관로공사 발주에 따른 시공도급비 감소분
A6: 1차 | B6: 1건 | C6: 49 | D6: 67366000 | G6: =J6 -> 0 | H6: =IF(A6="","",SUM(D6:F6)-G6) -> 67366000 | I6: =H6 -> 67366000 | J6: =SUM(K6:Q6) -> 0
A7: 2차 | B7: 2건 | C7: 283 | D7: 222907000 | G7: =J7 -> 0 | H7: =IF(A7="","",SUM(D7:F7)-G7) -> 222907000 | I7: =IF(A7="","",(I6+H7)) -> 290273000 | J7: =SUM(K7:Q7) -> 0
A8: 3차 | B8: 4건 | C8: 2229 | D8: 2631473000 | G8: =J8 -> 0 | H8: =IF(A8="","",SUM(D8:F8)-G8) -> 2631473000 | I8: =IF(A8="","",(I7+H8)) -> 2921746000 | J8: =SUM(K8:Q8) -> 0
A9: 4차 | B9: 1건 | C9: 7 | D9: 19077000 | G9: =J9 -> 0 | H9: =IF(A9="","",SUM(D9:F9)-G9) -> 19077000 | I9: =IF(A9="","",(I8+H9)) -> 2940823000 | J9: =SUM(K9:Q9) -> 0
A10: 5차 | B10: 1건 | C10: 192 | D10: 439232000 | G10: =J10 -> 0 | H10: =IF(A10="","",SUM(D10:F10)-G10) -> 439232000 | I10: =IF(A10="","",(I9+H10)) -> 3380055000 | J10: =SUM(K10:Q10) -> 0
A11: 6차 | B11: 12건 | C11: 1358 | D11: 1126967000 | G11: =J11 -> 0 | H11: =IF(A11="","",SUM(D11:F11)-G11) -> 1126967000 | I11: =IF(A11="","",(I10+H11)) -> 4507022000 | J11: =SUM(K11:Q11) -> 0
A12: 7차 | B12: 1건 | C12: 116 | D12: 188979000 | G12: =J12 -> 0 | H12: =IF(A12="","",SUM(D12:F12)-G12) -> 188979000 | I12: =IF(A12="","",(I11+H12)) -> 4696001000 | J12: =SUM(K12:Q12) -> 0
A13: 8차 | B13: 10건 | C13: 588 | D13: 428872000 | G13: =J13 -> 0 | H13: =IF(A13="","",SUM(D13:F13)-G13) -> 428872000 | I13: =IF(A13="","",(I12+H13)) -> 5124873000 | J13: =SUM(K13:Q13) -> 0
A14: 9차 | B14: 2건 | C14: 59 | D14: 69443000 | G14: =J14 -> 0 | H14: =IF(A14="","",SUM(D14:F14)-G14) -> 69443000 | I14: =IF(A14="","",(I13+H14)) -> 5194316000 | J14: =SUM(K14:Q14) -> 0
G15: =J15 -> 0 | H15: =IF(A15="","",SUM(D15:F15)-G15) | I15: =IF(A15="","",(I14+H15)) | J15: =SUM(K15:Q15) -> 0
G16: =J16 -> 0 | H16: =IF(A16="","",SUM(D16:F16)-G16) | I16: =IF(A16="","",(I15+H16)) | J16: =SUM(K16:Q16) -> 0
G17: =J17 -> 0 | H17: =IF(A17="","",SUM(D17:F17)-G17) | I17: =IF(A17="","",(I16+H17)) | J17: =SUM(K17:Q17) -> 0
G18: =J18 -> 0 | H18: =IF(A18="","",SUM(D18:F18)-G18) | I18: =IF(A18="","",(I17+H18)) | J18: =SUM(K18:Q18) -> 0
G19: =J19 -> 0 | H19: =IF(A19="","",SUM(D19:F19)-G19) | I19: =IF(A19="","",(I18+H19)) | J19: =SUM(K19:Q19) -> 0
G20: =J20 -> 0 | H20: =IF(A20="","",SUM(D20:F20)-G20) | I20: =IF(A20="","",(I19+H20)) | J20: =SUM(K20:Q20) -> 0
G21: =J21 -> 0 | H21: =IF(A21="","",SUM(D21:F21)-G21) | I21: =IF(A21="","",(I20+H21)) | J21: =SUM(K21:Q21) -> 0
G22: =J22 -> 0 | H22: =IF(A22="","",SUM(D22:F22)-G22) | I22: =IF(A22="","",(I21+H22)) | J22: =SUM(K22:Q22) -> 0
H23: =IF(A23="","",SUM(D23:F23)-G23) | I23: =IF(A23="","",(I22+H23)) | J23: =SUM(K23:Q23) -> 0
H24: =IF(A24="","",SUM(D24:F24)-G24) | I24: =IF(A24="","",(I23+H24)) | J24: =SUM(K24:Q24) -> 0
H25: =IF(A25="","",SUM(D25:F25)-G25) | I25: =IF(A25="","",(I24+H25)) | J25: =SUM(K25:Q25) -> 0
H26: =IF(A26="","",SUM(D26:F26)-G26) | I26: =IF(A26="","",(I25+H26)) | J26: =SUM(K26:Q26) -> 0
H27: =IF(A27="","",SUM(D27:F27)-G27) | I27: =IF(A27="","",(I26+H27)) | J27: =SUM(K27:Q27) -> 0
H28: =IF(A28="","",SUM(D28:F28)-G28) | I28: =IF(A28="","",(I27+H28)) | J28: =SUM(K28:Q28) -> 0
H29: =IF(A29="","",SUM(D29:F29)-G29) | I29: =IF(A29="","",(I28+H29)) | J29: =SUM(K29:Q29) -> 0
H30: =IF(A30="","",SUM(D30:F30)-G30) | I30: =IF(A30="","",(I29+H30)) | J30: =SUM(K30:Q30) -> 0
H31: =IF(A31="","",SUM(D31:F31)-G31) | I31: =IF(A31="","",(I30+H31)) | J31: =SUM(K31:Q31) -> 0
H32: =IF(A32="","",SUM(D32:F32)-G32) | I32: =IF(A32="","",(I31+H32)) | J32: =SUM(K32:Q32) -> 0
H33: =IF(A33="","",SUM(D33:F33)-G33) | I33: =IF(A33="","",(I32+H33)) | J33: =SUM(K33:Q33) -> 0
H34: =IF(A34="","",SUM(D34:F34)-G34) | I34: =IF(A34="","",(I33+H34)) | J34: =SUM(K34:Q34) -> 0
... H44: =IF(A44="","",SUM(D44:F44)-G44) | I44: =IF(A44="","",(I43+H44)) | J44: =SUM(K44:Q44) -> 0
H45: =IF(A45="","",SUM(D45:F45)-G45) | I45: =IF(A45="","",(I44+H45))
I46: =IF(A46="","",(I45+H46))
I47: =IF(A47="","",(I46+H47))
I48: =IF(A48="","",(I47+H48))
I49: =IF(A49="","",(I48+H49))
I50: =IF(A50="","",(I49+H50))
I51: =IF(A51="","",(I50+H51))
...

Sheet 투자현황
AB6: 0 | AG6: [금액단위:천원]
A7: 구 분 | C7: 2025년 투자 실적 | F7: 2026년 당초 투자한도액 | H7: 2024년 신규투자 잔여분 | I7: 2026년 사업계획 투자한도액 | L7: 2026년 본부투자 승인내역 | O7: ="금회 신청 내역("&품의서!E25&"차)" -> 금회 신청 내역(9차) | R7: 2026년 본부투자 이월 및 취소분 | U7: 2025년 본부투자 누계 | X7: 2026년 본부투자 누계 | AB7: 투자한도 잔 액 | AC7: 시설분담금 | AF7: 시설분담금 | AG7: 승인비율
C8: 규모(m) | D8: 금액 | E8: 구성비 | F8: 규모(m) | G8: 금액 | I8: 규모(m) | J8: 금액 | K8: 구성비 | L8: 전수 | M8: 규모(m) | N8: 금액 | O8: 전수 | P8: 규모(m) | Q8: 금액 | R8: 전수 | S8: 규모(m) | T8: 금액 | U8: 전수 | V8: 규모(m) | W8: 금액 | X8: 전수 | Y8: 규모(m) | Z8: 금액 | AA8: 구성비 | AC8: 일반 | AD8: 취사전용 | AE8: 수요가부담 | AJ8: 전수 | AK8: 규모 | AL8: 금액
A9: 수요개발 | B9: 공공택지 | C9: 3653 | D9: 2510347000 | E9: =D9/$D$28 -> 0.10826891 | F9: 1556 | G9: 1.0554306e+09 | I9: 1556 | J9: 1.0554306e+09 | K9: =J9/$J$28 -> 0.070994232 | L9: 2542 | M9: 172 | N9: 153713000 | O9: =AJ9 -> 0 | P9: =AK9 -> 0 | Q9: =AL9 -> 0 | U9: =L9+O9 -> 2542 | V9: =M9+P9 -> 172 | W9: =N9+Q9 -> 153713000 | X9: =L9+O9-R9 -> 2542 | Y9: =M9+P9-S9 -> 172 | Z9: =N9+Q9-T9 -> 153713000 | AA9: =Z9/$Z$28 -> 0.029592539 | AB9: =J9-Z9 -> 9.0171756e+08 | AG9: =IFERROR(Z9/J9,"") -> 0.14564009 | AI9: 공공택지 | AJ9: =용도별분석!AH9 -> 0 | AK9: =용도별분석!E9 -> 0 | AL9: =용도별분석!H9 -> 0
B10: 공동주택 | C10: 921 | D10: 1397023000 | E10: =D10/$D$28 -> 0.060252291 | F10: 906 | G10: 8.5119675e+08 | I10: 906 | J10: 8.5119675e+08 | K10: =J10/$J$28 -> 0.057256311 | L10: 4975 | M10: 228 | N10: 342643000 | O10: =AJ10 -> 450 | P10: =AK10 -> 8 | Q10: =AL10 -> 33889000 | U10: =L10+O10 -> 5425 | V10: =M10+P10 -> 236 | W10: =N10+Q10 -> 376532000 | X10: =L10+O10-R10 -> 5425 | Y10: =M10+P10-S10 -> 236 | Z10: =N10+Q10-T10 -> 376532000 | AA10: =Z10/$Z$28 -> 0.072489236 | AB10: =J10-Z10 -> 4.7466475e+08 | AG10: =IFERROR(Z10/J10,"") -> 0.44235601 | AI10: 공동주택 | AJ10: =용도별분석!AH11 -> 450 | AK10: =용도별분석!E11 -> 8 | AL10: =용도별분석!H11 -> 33889000
B11: 산업용 | C11: 595 | D11: 450233000 | E11: =D11/$D$28 -> 0.019418127 | F11: 325 | G11: 2.8756827e+08 | I11: 325 | J11: 2.8756827e+08 | K11: =J11/$J$28 -> 0.01934347 | L11: 0 | M11: 0 | N11: 0 | O11: =AJ11 -> 0 | P11: =AK11 -> 0 | Q11: =AL11 -> 0 | U11: =L11+O11 -> 0 | V11: =M11+P11 -> 0 | W11: =N11+Q11 -> 0 | X11: =L11+O11-R11 -> 0 | Y11: =M11+P11-S11 -> 0 | Z11: =N11+Q11-T11 -> 0 | AA11: =Z11/$Z$28 -> 0 | AB11: =J11-Z11 -> 2.8756827e+08 | AG11: =IFERROR(Z11/J11,"") -> 0 | AI11: 산업용 | AJ11: =용도별분석!AH14 -> 0 | AK11: =용도별분석!E14 -> 0 | AL11: =용도별분석!H14 -> 0
B12: 업무용 | C12: 514 | D12: 651328000 | E12: =D12/$D$28 -> 0.028091166 | F12: 498 | G12: 4.3942951e+08 | I12: 498 | J12: 4.3942951e+08 | K12: =J12/$J$28 -> 0.029558516 | L12: 10 | M12: 155 | N12: 128275000 | O12: =AJ12 -> 0 | P12: =AK12 -> 0 | Q12: =AL12 -> 0 | U12: =L12+O12 -> 10 | V12: =M12+P12 -> 155 | W12: =N12+Q12 -> 128275000 | X12: =L12+O12-R12 -> 10 | Y12: =M12+P12-S12 -> 155 | Z12: =N12+Q12-T12 -> 128275000 | AA12: =Z12/$Z$28 -> 0.024695263 | AB12: =J12-Z12 -> 3.1115451e+08 | AG12: =IFERROR(Z12/J12,"") -> 0.29191258 | AI12: 업무용 | AJ12: =용도별분석!AH17 -> 0 | AK12: =용도별분석!E17 -> 0 | AL12: =용도별분석!H17 -> 0
B13: 영업용 | C13: 3 | D13: 18447000 | E13: =D13/$D$28 -> 0.0007956018 | F13: 275 | G13: 1.8295611e+08 | I13: 275 | J13: 1.8295611e+08 | K13: =J13/$J$28 -> 0.012306664 | L13: 1 | M13: 35 | N13: 61362000 | O13: =AJ13 -> 0 | P13: =AK13 -> 0 | Q13: =AL13 -> 0 | U13: =L13+O13 -> 1 | V13: =M13+P13 -> 35 | W13: =N13+Q13 -> 61362000 | X13: =L13+O13-R13 -> 1 | Y13: =M13+P13-S13 -> 35 | Z13: =N13+Q13-T13 -> 61362000 | AA13: =Z13/$Z$28 -> 0.011813297 | AB13: =J13-Z13 -> 1.2159411e+08 | AG13: =IFERROR(Z13/J13,"") -> 0.33539191 | AI13: 영업용 | AJ13: =용도별분석!AH29 -> 0 | AK13: =용도별분석!E29 -> 0 | AL13: =용도별분석!H29 -> 0
B14: 연료전지용 | C14: 0 | D14: 0 | E14: =D14/$D$28 -> 0 | F14: 735 | G14: 6.1043548e+08 | I14: 735 | J14: 6.1043548e+08 | K14: =J14/$J$28 -> 0.041061345 | L14: 1 | M14: 470 | N14: 474456000 | O14: =AJ14 -> 0 | P14: =AK14 -> 0 | Q14: =AL14 -> 0 | U14: =L14+O14 -> 1 | V14: =M14+P14 -> 470 | W14: =N14+Q14 -> 474456000 | X14: =L14+O14-R14 -> 1 | Y14: =M14+P14-S14 -> 470 | Z14: =N14+Q14-T14 -> 474456000 | AA14: =Z14/$Z$28 -> 0.091341382 | AB14: =J14-Z14 -> 1.3597948e+08 | AG14: =IFERROR(Z14/J14,"") -> 0.77724185 | AI14: 연료전지용 | AJ14: =용도별분석!AH20 -> 0 | AK14: =용도별분석!E20 -> 0 | AL14: =용도별분석!H20 -> 0
B15: 주택용 (지자체) | C15: 6377 | D15: 4653481000 | E15: =D15/$D$28 -> 0.20070027 | K15: =J15/$J$28 -> 0 | L15: 0 | M15: 0 | N15: 0 | O15: =AJ15 -> 0 | P15: =AK15 -> 0 | Q15: =AL15 -> 0 | U15: =L15+O15 -> 0 | V15: =M15+P15 -> 0 | W15: =N15+Q15 -> 0 | X15: =L15+O15-R15 -> 0 | Y15: =M15+P15-S15 -> 0 | Z15: =N15+Q15-T15 -> 0 | AA15: =Z15/$Z$28 -> 0 | AB15: =J15-Z15 -> 0 | AG15: =IFERROR(Z15/J15,"") | AI15: 주택용 | AJ15: =용도별분석!AH32 -> 0 | AK15: =용도별분석!E32 -> 0 | AL15: =용도별분석!H32 -> 0
B16: 소 계 | C16: 15603 | D16: 10662598000 | E16: =SUM(E9:E15) -> 0.41752637 | F16: =SUM(F9:F15) -> 4295 | G16: =SUM(G9:G15) -> 3.4270167e+09 | H16: =SUM(H9:H15) -> 0 | I16: =SUM(I9:I15) -> 4295 | J16: =SUM(J9:J15) -> 3.4270167e+09 | K16: =SUM(K9:K15) -> 0.23052054 | L16: 7529 | M16: 1060 | N16: 1160449000 | O16: =SUM(O9:O15) -> 450 | P16: =SUM(P9:P15) -> 8 | Q16: =SUM(Q9:Q15) -> 33889000 | R16: =SUM(R9:R15) -> 0 | S16: =SUM(S9:S15) -> 0 | T16: =SUM(T9:T15) -> 0 | U16: =SUM(U9:U15) -> 7979 | V16: =SUM(V9:V15) -> 1068 | ... Z16: =SUM(Z9:Z15) -> 1194338000 | AA16: =Z16/$Z$28 -> 0.22993172 | AB16: =SUM(AB9:AB15) -> 2.2326787e+09 | AG16: =IFERROR(Z16/J16,"") -> 0.34850662 | AI16: 소계 | AJ16: =SUM(AJ9:AJ15) -> 450 | AK16: =SUM(AK9:AK15) -> 8 | AL16: =SUM(AL9:AL15) -> 33889000
A17: 배관투자재원 | C17: 0 | D17: 0 | E17: =D17/$D$28 -> 0 | K17: =J17/J28 -> 0 | L17: 0 | M17: 0 | N17: 0 | P17: =신규투자계획서!F61 -> 0 | Q17: =신규투자계획서!G61 -> 0 | U17: =L17+O17 -> 0 | V17: =M17+P17 -> 0 | W17: =N17+Q17 -> 0 | X17: =L17+O17-R17 -> 0 | Y17: =M17+P17-S17 -> 0 | Z17: =N17+Q17-T17 -> 0 | AA17: =Z17/$Z$28 -> 0 | AB17: =J17-Z17 -> 0 | AG17: =IFERROR(Z17/J17,"") | AI17: =Y16-Y9+S16 -> 896
A18: 투자보수율가산 | C18: 3051 | D18: 1879144000 | E18: =D18/$D$28 -> 0.081045718 | F18: 3004 | G18: 1.695844e+09 | I18: 3004 | J18: 1.695844e+09 | K18: =J18/J28 -> 0.11407207 | L18: 0 | M18: 1225 | N18: 704740000 | P18: =신규투자계획서!F60 -> 51 | Q18: =신규투자계획서!G60 -> 35554000 | U18: =L18+O18 -> 0 | V18: =M18+P18 -> 1276 | W18: =N18+Q18 -> 740294000 | X18: =L18+O18-R18 -> 0 | Y18: =M18+P18-S18 -> 1276 | Z18: =N18+Q18-T18 -> 740294000 | AA18: =Z18/$Z$28 -> 0.14252002 | AB18: =J18-Z18 -> 9.5555001e+08 | AG18: =IFERROR(Z18/J18,"") -> 0.43653425 | AI18: =Z16-Z9+T16 -> 1040625000
A19: 합 계 | C19: 19948 | D19: 14431426000 | E19: =SUM(E16+SUM(E17:E18)) -> 0.49857208 | F19: =F16+F17+F18 -> 7299 | G19: =G16+G17+G18 -> 5.1228607e+09 | H19: =SUM(H16+SUM(H17:H18)) -> 0 | I19: =I16+I17+I18 -> 7299 | J19: =J16+J17+J18 -> 5.1228607e+09 | K19: =SUM(K16+SUM(K17:K18)) -> 0.3445926 | L19: 7529 | M19: 2285 | N19: 1865189000 | O19: =SUM(O16:O18) -> 450 | P19: =SUM(P16:P18) -> 59 | Q19: =SUM(Q16:Q18) -> 69443000 | R19: =SUM(R16:R18) -> 0 | S19: =SUM(S16:S18) -> 0 | T19: =SUM(T16:T18) -> 0 | U19: =SUM(U16:U18) -> 7979 | V19: =SUM(V16:V18) -> 2344 | ... AB19: =SUM(AB16:AB18) -> 3.1882287e+09 | AC19: =AC16+#REF!+AC17 -> #REF! | AD19: =AD16+#REF!+AD17 -> #REF! | AE19: =AE16+#REF!+AE17 -> #REF! | AF19: =AF16+#REF!+AF17 -> #REF! | AG19: =IFERROR(Z19/J19,"") -> 0.37764681 | AI19: 소계 | AJ19: =AJ16 -> 450 | AK19: =AK16 -> 8 | AL19: =AL16 -> 33889000
A20: 기본계획 | B20: 계획배관 | C20: 2100 | D20: 2809538000 | E20: =D20/$D$28 -> 0.12117274 | F20: 2828 | G20: 2.031952e+09 | I20: 2828 | J20: 2.031952e+09 | K20: =J20/$J$28 -> 0.13668059 | L20: 0 | M20: 2345 | N20: 1083876000 | U20: =L20+O20 -> 0 | V20: =M20+P20 -> 2345 | W20: =N20+Q20 -> 1083876000 | Y20: =M20+P20-S20 -> 2345 | Z20: =N20+Q20-T20 -> 1083876000 | AA20: =Z20/$Z$28 -> 0.20866578 | AB20: =J20-Z20 -> 9.4807601e+08 | AF20: =SUM(AC20:AE20) -> 0 | AG20: =IFERROR(Z20/J20,"") -> 0.53341614
B21: Loop | C21: 272 | D21: 228087000 | E21: =D21/$D$28 -> 0.0098371783 | F21: 749 | G21: 6.2698784e+08 | I21: 749 | J21: 6.2698784e+08 | K21: =J21/$J$28 -> 0.04217475 | L21: 0 | M21: 0 | N21: 0 | U21: =L21+O21 -> 0 | V21: =M21+P21 -> 0 | W21: =N21+Q21 -> 0 | Y21: =M21+P21-S21 -> 0 | Z21: =N21+Q21-T21 -> 0 | AA21: =Z21/$Z$28 -> 0 | AB21: =J21-Z21 -> 6.2698784e+08 | AF21: =SUM(AC21:AE21) -> 0 | AG21: =IFERROR(Z21/J21,"") -> 0
B22: 이설배관 | C22: 40 | D22: 22356000 | E22: =D22/$D$28 -> 0.0009641933 | F22: 624 | G22: 7.664525e+08 | I22: 624 | J22: 7.664525e+08 | K22: =J22/$J$28 -> 0.051555933 | L22: 0 | M22: 192 | N22: 439232000 | U22: =L22+O22 -> 0 | V22: =M22+P22 -> 192 | W22: =N22+Q22 -> 439232000 | Y22: =M22+P22-S22 -> 192 | Z22: =N22+Q22-T22 -> 439232000 | AA22: =Z22/$Z$28 -> 0.084560123 | AB22: =J22-Z22 -> 3.272205e+08 | AF22: =SUM(AC22:AE22) -> 0 | AG22: =IFERROR(Z22/J22,"") -> 0.57307139 | AJ22: =Y16-S16-AJ21 -> 1068 | AK22: =Z16-T16-AK21 -> 1194338000
B23: 지역 정압기 | C23: 0 | D23: 750428000 | E23: =D23/$D$28 -> 0.032365256 | F23: 3 | G23: 3.3804502e+08 | I23: 3 | J23: 3.3804502e+08 | K23: =J23/$J$28 -> 0.022738821 | L23: 0 | N23: 109867000 | U23: =L23+O23 -> 0 | W23: =N23+Q23 -> 109867000 | Y23: =M23+P23 -> 0 | Z23: =N23+Q23-T23 -> 109867000 | AA23: =Z23/$Z$28 -> 0.021151389 | AB23: =J23-Z23 -> 2.2817802e+08 | AF23: =SUM(AC23:AE23) -> 0 | AG23: =IFERROR(Z23/J23,"") -> 0.325007 | AJ23: =Y16+S16-AJ21 -> 1068 | AK23: =Z16+T16-AK21 -> 1194338000
B24: 인입배관 | D24: 3522977000 | E24: =D24/$D$28 -> 0.15194269 | F24: 856.647 | G24: 3.230129e+09 | I24: 856.647 | J24: 3.230129e+09 | K24: =J24/$J$28 -> 0.21727676 | N24: 1076709000 | W24: =N24+Q24 -> 1076709000 | Z24: =N24+Q24-T24 -> 1076709000 | AA24: =Z24/$Z$28 -> 0.207286 | AB24: =J24-Z24 -> 2.15342e+09 | AF24: =SUM(AC24:AE24) -> 0 | AG24: =IFERROR(Z24/J24,"") -> 0.33333312 | AJ24: =Z19/J19 -> 0.37764681 | AK24: 수요개발
B25: 공급시설물 개선 | D25: 1421410000 | E25: =D25/$D$28 -> 0.06130408 | F25: 95 | G25: 2.7499997e+09 | I25: 95 | J25: 2.7499997e+09 | K25: =J25/$J$28 -> 0.18498054 | N25: 550000000 | W25: =N25+Q25 -> 550000000 | Z25: =N25+Q25-T25 -> 550000000 | AA25: =Z25/$Z$28 -> 0.10588497 | AB25: =J25-Z25 -> 2.1999997e+09 | AG25: =IFERROR(Z25/J25,"") -> 0.20000002 | AJ25: =Z27/J27 -> 0.33454733 | AK25: 기본계획
D26: 0 | H26: =G26/$J$28 -> 0 | K26: =J26/$J$28 -> 0 | N26: 0 | W26: =N26+Q26 -> 0 | Z26: =N26+Q26-T26 -> 0 | AA26: =Z26/$Z$28 -> 0 | AB26: =J26-Z26 -> 0 | AG26: =IFERROR(Z26/J26,"") | AJ26: =Z28/J28 -> 0.34939909 | AK26: 전체
A27: 소 계 | C27: =SUM(C20:C22) -> 2412 | D27: =SUM(D20:D26) -> 8754796000 | E27: =SUM(E20:E26) -> 0.37758614 | F27: =SUM(F20:F22) -> 4201 | G27: =SUM(G20:G26) -> 9.7435661e+09 | H27: =SUM(H20:H26) -> 0 | I27: =SUM(I20:I22) -> 4201 | J27: =SUM(J20:J26) -> 9.7435661e+09 | K27: =SUM(K20:K26) -> 0.6554074 | L27: 0 | M27: 2537 | N27: 3259684000 | O27: =SUM(O20:O24) -> 0 | P27: =SUM(P20:P24) -> 0 | Q27: =SUM(Q20:Q26) -> 0 | R27: =SUM(R20:R24) -> 0 | S27: =SUM(S20:S24) -> 0 | T27: =SUM(T20:T26) -> 0 | U27: =SUM(U20:U24) -> 0 | V27: =SUM(V20:V22) -> 2537 | W27: =SUM(W20:W26) -> 3259684000 | X27: =SUM(X20:X24) -> 0 | Y27: =SUM(Y20:Y22) -> 2537 | Z27: =SUM(Z20:Z26) -> 3259684000 | AA27: =SUM(AA20:AA26) -> 0.62754827 | AB27: =SUM(AB20:AB26) -> 6.4838821e+09 | AC27: =SUM(AC17:AC22) -> #REF! | AD27: =SUM(AD17:AD22) -> #REF! | AE27: =SUM(AE17:AE22) -> #REF! | AF27: =SUM(AF17:AF22) -> #REF! | AG27: =IFERROR(Z27/J27,"") -> 0.33454733
A28: 총 합 계 | C28: =C19+C27 -> 22360 | D28: =SUM(D19,D27) -> 23186222000 | E28: =SUM(E19,E27) -> 0.87615822 | F28: =F27+F19 -> 11500 | G28: =G27+G19 -> 1.4866427e+10 | H28: =H27+H19 -> 0 | I28: =I27+I19 -> 11500 | J28: =J27+J19 -> 1.4866427e+10 | K28: =K27+K19 -> 1 | L28: 7529 | M28: 4822 | N28: 5124873000 | O28: =O27+O19 -> 450 | P28: =P27+P19 -> 59 | Q28: =Q27+Q19 -> 69443000 | R28: =R27+R19 -> 0 | S28: =S27+S19 -> 0 | T28: =T27+T19 -> 0 | U28: =U27+U19 -> 7979 | V28: =V27+V19 -> 4881 | ... Z28: =Z27+Z19 -> 5194316000 | AA28: =SUM(AA19,AA27) -> 1 | AB28: =ROUND(SUM(AB19,AB27),0) -> 9672110837 | AC28: =SUM(AC22+SUM(AC23:AC27)) -> #REF! | AD28: =SUM(AD22+SUM(AD23:AD27)) -> #REF! | AE28: =SUM(AE22+SUM(AE23:AE27)) -> #REF! | AF28: =SUM(AF22+SUM(AF23:AF27)) -> #REF! | AG28: =IFERROR(Z28/J28,"") -> 0.34939909 | AJ28: =Z28 -> 5194316000
Z30: =Z28=요약보고!I62 -> TRUE | AB30: =ROUND((J28-N28-Q28+T28),0) -> 9672110837
AB31: =AB28-AB30 -> 0
AB32: =Z28/J28 -> 0.34939909 | AG32: 전체
AB33: =Z19/J19 -> 0.37764681 | AG33: 수요개발
AB34: =Z27/J27 -> 0.33454733 | AG34: 기본계획 | AK34: 구분 | AL34: 투자누계(%)
AK35: 수요개발투자 | AL35: =AB33 -> 0.37764681
AK36: 기본계획투자 | AL36: =AB34 -> 0.33454733
AK37: 전체 투자 | AL37: =AB32 -> 0.34939909
AH39: =10908669800-10741377000 -> 167292800
AH40: =818047800-650755000 -> 167292800
AH41: =215530800-48238000 -> 167292800

Sheet 신규투자계획서
A1: (첨부 1)
A2: 신 규 투 자 계 획 서
A4: 사업부명 : 대성에너지주식회사
A6: 1. | B6: 투자사업장 | C6: : | D6: 대성에너지주식회사
A8: 2. | B8: 투자명 | C8: : | D8: =품의서!E25 -> 9
A10: 3. | B10: 총투자예상금액 | C10: : | D10: 금회승인(관로,시설공사) | E10: ⇒ | F10: =IF(F16=0,G50,G50-F16) -> 33889000 | G10: =IF(G16=0,F50,F50-G16) -> 8
D12: 금회배관투자재원구간 | E12: ⇒ | F12: =용도별분석!H38 -> 0 | G12: =용도별분석!E38 -> 0
D14: 금회투자보수율가산구간 | E14: ⇒ | F14: =용도별분석!H35 -> 35554000 | G14: =용도별분석!E35 -> 51
D16: 과년도 경제성분석 승인 구간 | E16: ⇒ | F16: =N37 -> 0 | G16: =M37 -> 0
D18: 금회취소(관로,시설공사) | E18: ⇒ | F18: =취소분!G103 -> 0 | G18: =취소분!F103 -> 0
D20: 금회이월(관로,시설공사) | E20: ⇒ | F20: =이월분!L16 -> 0 | G20: =이월분!K16 -> 0
D22: 8 | E22: ⇒ | F22: =투자현황!N16 -> 1160449000 | G22: =투자현황!M16 -> 1060 | M22: D22 입력할 것
D24: 본부투자 취소구간 | E24: ⇒ | F24: =SUM(취소분!G5:G80) -> 0 | G24: =SUM(취소분!F5:F80) -> 0
D26: 본부투자이월구간 | E26: ⇒ | F26: =이월분!L10 -> 0 | G26: =이월분!K10 -> 0
D28: 배관투자재원구간 | E28: ⇒ | F28: =투자현황!N17 -> 0 | G28: =투자현황!M17 -> 0
D30: 투자보수율가산구간 | E30: ⇒ | F30: =투자현황!N18 -> 704740000 | G30: =투자현황!M18 -> 1225
B32: (VAT별도) | D32: 2026년투자누계 | E32: ⇒ | F32: =(F10+F12+F14+F16+F22+F28+F30)-(F18+F20+F24+F26) -> 1934632000 | G32: =(G10+G12+G14+G16+G22+G28+G30)-(G18+G20+G24+G26) -> 2344
M35: --> 과년도 투자승인_입력
M36: 공사규모(m) | N36: 투자금액(원) | O36: 비 고
A38: 4. | B38: 투자내역 | C38: :
B40: 자 산 명 | D40: 적 요( 내 용) | F40: 공사규모(m) | G40: 투자금액(원) | H40: 비 고 | L40: 적 요( 내 용) | M40: 공사규모(m) | N40: 투자금액(원) | O40: 비 고
D41: ="관로공사 "&품의서!E25&" 차 ▷공공택지" -> 관로공사 9 차 ▷공공택지 | F41: =M41 -> 0 | G41: =N41 -> 0 | L41: ▷공공택지 | M41: =공공택지!D7 -> 0 | N41: =공공택지!G7 -> 0
D42: ▷공동주택 | F42: =M42 -> 8 | G42: =N42 -> 33889000 | L42: ▷공동주택 | M42: =공동주택!D7 -> 8 | N42: =공동주택!G7 -> 33889000
B43: 공급설비 | D43: ▷산업용 | F43: =M43 -> 0 | G43: =N43 -> 0 | L43: ▷산업용 | M43: =산업용!D7 -> 0 | N43: =산업용!G7 -> 0
B44: (배관공사) | D44: ▷업무용 | F44: =M44 -> 0 | G44: =N44 -> 0 | L44: ▷업무용 | M44: =업무용!D7 -> 0 | N44: =업무용!G7 -> 0
D45: ▷연료전지 | F45: =M45 -> 0 | G45: =N45 -> 0 | L45: ▷연료전지 | M45: =연료전지!D7 -> 0 | N45: =연료전지!G7 -> 0
D46: ▷열병합 | F46: =M46 -> 0 | G46: =N46 -> 0 | L46: ▷열병합 | M46: =열병합!D7 -> 0 | N46: =열병합!G7 -> 0
D47: ▷열전용설비 | F47: =M47 -> 0 | G47: =N47 -> 0 | L47: ▷열전용설비 | M47: =열전용설비!D7 -> 0 | N47: =열전용설비!G7 -> 0
D48: ▷영업용 | F48: =M48 -> 0 | G48: =N48 -> 0 | L48: ▷영업용 | M48: =영업용!D7 -> 0 | N48: =영업용!G7 -> 0
D49: ▷주택용 | F49: =M49 -> 0 | G49: =N49 -> 0 | L49: ▷주택용 | M49: =주택용!D7 -> 0 | N49: =주택용!G7 -> 0
D50: 공급설비 합계 | F50: =SUM(F41:F49) -> 8 | G50: =SUM(G41:G49) -> 33889000 | L50: 공급설비 합계 | M50: =기본데이타!G7 -> 59 | N50: =기본데이타!H7 -> 69443000
B52: 자 산 명 | D52: 적 요( 내 용) | F52: 공사규모(m) | G52: 투자금액(원) | H52: 비 고
F54: =SUMIF(M54:M92,B54,O54:O92) -> 0 | G54: =SUMIF(M54:M92,B54,P54:P92) -> 0
F55: =SUMIF(M55:M93,B55,O55:O93) -> 0 | G55: =SUMIF(M55:M93,B55,P55:P93) -> 0
F56: =SUMIF(M56:M94,B56,O56:O94) -> 0 | G56: =SUMIF(M56:M94,B56,P56:P94) -> 0
F57: =SUMIF(M57:M95,B57,O57:O95) -> 0 | G57: =SUMIF(M57:M95,B57,P57:P95) -> 0
F58: =SUMIF($M$53:$M$91,B58,$O$53:$O$91) -> 0 | G58: =SUMIF($M$53:$M$91,B58,$P$53:$P$91) -> 0
F59: =SUMIF($M$53:$M$91,B59,$O$53:$O$91) -> 0 | G59: =SUMIF($M$53:$M$91,B59,$P$53:$P$91) -> 0
B60: 공급설비 (배관공사) | D60: 투자보수율가산구간 | F60: =G14 -> 51 | G60: =F14 -> 35554000
F61: =G12 -> 0 | G61: =F12 -> 0
...

Sheet 품의서
A3: 『세계를 아는 기업, 세계가 아는 기업』
D9: =3142630950-3081150849+3142630950-1271852761+100000 -> 1932358290
F16: 2026. 05.
A17: 문서번호 | B17: : | C17: 제 26 - 호 | J17: 1 | K17: 67366000
J18: 2 | K18: 222907000
A19: 수신 | B19: : | C19: 회 장 | J19: 3 | K19: 2631473000
J20: 4 | K20: 19077000
A21: 제목 | B21: : | C21: 신규투자 착수 품의서 | J21: 5 | K21: 439232000
J22: 6 | K22: 1126967000
B23: 1. | C23: 투자사업장명 | D23: : | E23: 대성에너지주식회사 | J23: 7 | K23: 188979000 | L23: 4696001000
J24: 8 | K24: 428872000 | L24: 428872000
B25: 2. | C25: 투자명 | D25: : | E25: 9 | J25: 9 | K25: 69443000 | L25: 69443000
J26: 10
B27: 3. | C27: 투자내용 | D27: : | E27: ="신규 관로공사(총 "&COUNTIF(기본데이타!A8:A103,">0")&" 건) 및 시설투자(총 "&COUNTIF(기본데이타!I8:I103,">0")&" 건)" -> 신규 관로공사(총 2 건) 및 시설투자(총 0 건) | J27: 11
J28: 12
B29: 4. | C29: 투자금액 | D29: : | E29: 1차 ~ 7차 : 4,696,001,000원 | J29: 13
E30: 8차 : 428,872,000원 | J30: 14
E31: 9차 : 69,443,000원 | J31: 15 | N31: --> E33 수식변경 : = " "&$E$27&"차 : "&TEXT(신규투자계획서!$G$64,"###,0")&"원"
E32: =" "&"계 : "&TEXT(요약보고!H62,"###,0")&"원" -> 계 : 5,194,316,000원 | J32: 16
C33: (2026년 사업계획 투자한도액 : 14,866,426,837원) | J33: 17 | K33: =SUM(K17:K32) -> 5194316000 | L33: 290273000
J34: 18
B35: 5. | C35: 투자사유 | D35: : | E35: 첨부 자료 참조 | J35: 19
J36: 20
A38: 첨부: | B38: 1. 신규 투자 계획서 ---- 1부
B39: 2. 신규 배관 투자 경제성 분석서(총괄) ---- 1부
B40: 3. 신규 배관 투자 경제성 분석서(용도별) ---- 각 1부
B41: 4. 신규 배관 투자 경제성 분석서(구간별) ---- 각 1부
A44: 대성에너지주식회사 대표이사
A47: DGBB-0102-01 "고객과 함께할 대성 100년, 그 첫걸음은 안전입니다."

Sheet 용도별분석
C2: 신규 배관 투자 경제성 분석서(용도별)
C4: 공급대상 총계 | F4: 투자금액 | I4: 가 정 용 [MJ/(월)] | Q4: 일 반 용 [MJ/(월)] | Z4: 산 업 용 [MJ/(월)] | AB4: 연 료 전 지 [MJ/(전,월)] | AD4: 열 병 합 [MJ/(전,월)] | AF4: 열전용설비 (주택용 外) [MJ/(전,월)] | AH4: 수 요 전 수 | AI4: 용도별 표준가스 소비량 합계 | AT4: 가 스 소 비 량 합 계 | AU4: 시설분담금 | AY4: 기 타 이 익 | AZ4: 연 간 판 매 량 [MJ/년] | BL4: 연 간 | BM4: 연 간 | BN4: 연 간 | BO4: 연 간 | BP4: 경제성분석 | BT4: 비고
E5: 길이 | F5: 배관투자금액 | G5: 시설투자 | H5: 총 투자금액 | I5: 공동주택 전 수 | K5: 단독주택 전 수 | M5: 원 룸 전 수 | O5: 중앙난방 (중집) | Q5: 영업용1 (영업용) | S5: 영업용2 (목욕탕 등) | U5: 업무난방용 | W5: 냉난방용 | AI5: 주택용 | AL5: 주택용 외 | AZ5: 가 정 용 | BC5: 일 반 용 | BH5: 산 업 용 | BI5: 연료전지 | BJ5: 열 병 합 | BK5: 열전용설비 (주택용 外) | BL5: 판 매 량 | BM5: 판 매 액 | BN5: 판 매 원 가 | BO5: 판 매 수 익 | BP5: 회 수 | BQ5: NPV | BR5: IRR | BS5: 100m
E6: (m) | F6: (원) | I6: 취사 | J6: 난방 | K6: 취사 | L6: 난방 | M6: 취사 | N6: 난방 | O6: 전수 | P6: 판매량 | Q6: 전수 | R6: 판매량 | S6: 전수 | T6: 판매량 | U6: 전수 | V6: 난 방 판매량 | W6: 전수 | X6: 난 방 판매량 | Y6: 냉 방 판매량 | Z6: 전수 | AA6: 판매량 | AB6: 전수 | AC6: 판매량 | AD6: 전수 | AE6: 판매량 | AF6: 전수 | AG6: 판매량 | AI6: 취사 | AJ6: 난방 | AK6: 중앙 | AL6: 영업용1 | AM6: 영업용2 | AN6: 업무난방 | AO6: 냉난 방용 | AP6: 산업용 | AQ6: 연료전지 | AR6: 열병합 | AS6: 열전용설비 (주택용 外) | AU6: 일반 | AV6: 취사전용 | AW6: 수요가부담금 | AX6: 총 시설분담금 | AZ6: 취사용 | BA6: 개별난방용 | BB6: 중앙난방용 (중집용) | BC6: 영업용1 (영업용) | BD6: 영업용2 (목욕탕 등) | BE6: 업무난방용 | BF6: 냉난방용 (난방용) | BG6: 냉난방용 (냉방용) | BL6: [MJ/년] | BM6: [원/년] | BN6: [원/년] | BO6: [원/년] | BP6: 년 수 | BQ6: (원) | BR6: (%) | BS6: 환산세대수
C7: =SUM(C8:C39) -> 2 | D7: 용도별 | E7: =SUM(E8:E39) -> 59 | F7: =SUM(F8:F39) -> 69443000 | G7: =SUM(G8:G39) -> 0 | H7: =SUM(H8:H39) -> 69443000 | I7: =SUM(I8:I39) -> 0 | J7: =SUM(J8:J39) -> 450 | K7: =SUM(K8:K39) -> 0 | L7: =SUM(L8:L39) -> 0 | ... O7: =SUM(O8:O39) -> 0 | P7: =IF(O7=0,0,SUM(P8:P39)) -> 0 | Q7: =SUM(Q8:Q39) -> 0 | R7: =SUM(R8:R39) -> 0 | S7: =SUM(S8:S39) -> 0 | T7: =IF(S7=0,0,SUM(T8:T39)) -> 0 | U7: =SUM(U8:U39) -> 0 | V7: =IF(U7=0,0,SUM(V8:V39)) -> 0 | Y7: =IF(U7=0,0,SUM(Y8:Y39)) -> 0 | Z7: =SUM(Z8:Z39) -> 0 | AA7: =IF(Z7=0,0,SUM(AA8:AA39)) -> 0 | AB7: =SUM(AB8:AB39) -> 0 | AC7: =IF(AB7=0,0,SUM(AC8:AC39)) -> 0 | AD7: =SUM(AD8:AD39) -> 0 | AE7: =IF(AD7=0,0,SUM(AE8:AE39)) -> 0 | AF7: =SUM(AF8:AF39) -> 0 | AG7: =IF(AF7=0,0,SUM(AG8:AG39)) -> 0 | AH7: =SUM(AH8:AH39) -> 450 | AI7: =SUM(AI8:AI39) -> 0 | AJ7: =SUM(AJ8:AJ39) -> 1908 | AK7: =SUM(AK8:AK39) -> 0 | AL7: =SUM(AL8:AL39) -> 0 | AM7: =SUM(AM8:AM39) -> 0 | AN7: =SUM(AN8:AN39) -> 0 | AO7: =SUM(AO8:AO39) -> 0 | ... BE7: =SUM(BE8:BE39) -> 0 | BG7: =SUM(BG8:BG39) -> 0 | BH7: =SUM(BH8:BH39) -> 0 | BI7: =SUM(BI8:BI39) -> 0 | BJ7: =SUM(BJ8:BJ39) -> 0 | BK7: =SUM(BK8:BK39) -> 0 | BL7: =SUM(BL8:BL39) -> 11782800 | BM7: =SUM(BM8:BM39) -> 278499439 | BN7: =SUM(BN8:BN39) -> 245665488 | BO7: =SUM(BO8:BO39) -> 32833951 | BP7: =[5]총괄!$D$47 -> 4 | BQ7: =[11]총괄!$D$45 -> 3.3639958e+08 | BR7: =[11]총괄!$D$46 -> 80.658151 | BS7: =[11]총괄!$F$39 -> 5962.5
C9: =공공택지!C7 -> 0 | D9: 공공택지 | E9: =IF($C9="","",공공택지!D$7) -> 0 | F9: =IF($C9="","",공공택지!E$7) -> 0 | G9: =IF($C9="","",공공택지!F$7) -> 0 | H9: =IF($C9="","",공공택지!G$7) -> 0 | I9: =IF($C9="","",공공택지!H$7) -> 0 | J9: =IF($C9="","",공공택지!I$7) -> 0 | K9: =IF($C9="","",공공택지!J$7) -> 0 | L9: =IF($C9="","",공공택지!K$7) -> 0 | ... BS9: =IF($C9="","",공공택지!BR$7) -> #DIV/0!
C11: =공동주택!C7 -> 1 | D11: 공동주택 | E11: =IF($C11="","",공동주택!D$7) -> 8 | F11: =IF($C11="","",공동주택!E7) -> 33889000 | G11: =IF($C11="","",공동주택!F7) -> 0 | H11: =IF($C11="","",공동주택!G7) -> 33889000 | I11: =IF($C11="","",공동주택!H7) -> 0 | J11: =IF($C11="","",공동주택!I7) -> 450 | K11: =IF($C11="","",공동주택!J7) -> 0 | L11: =IF($C11="","",공동주택!K7) -> 0 | M11: =IF($C11="","",공동주택!L7) -> 0 | ... BS11: =IF($C11="","",공동주택!BR7) -> 5962.5
C14: =산업용!C7 -> 0 | D14: 산업용 | E14: =IF($C14="","",산업용!D$7) -> 0 | F14: =IF($C14="","",산업용!E$7) -> 0 | G14: =IF($C14="","",산업용!F$7) -> 0 | H14: =IF($C14="","",산업용!G$7) -> 0 | I14: =IF($C14="","",산업용!H$7) -> 0 | J14: =IF($C14="","",산업용!I$7) -> 0 | K14: =IF($C14="","",산업용!J$7) -> 0 | L14: =IF($C14="","",산업용!K$7) -> 0 | ... BS14: =IF($C14="","",산업용!BR$7) -> #DIV/0!
C17: =업무용!C7 -> 0 | D17: 업무용 | E17: =IF($C17="","",업무용!D$7) -> 0 | F17: =IF($C17="","",업무용!E$7) -> 0 | G17: =IF($C17="","",업무용!F$7) -> 0 | H17: =IF($C17="","",업무용!G$7) -> 0 | I17: =IF($C17="","",업무용!H$7) -> 0 | J17: =IF($C17="","",업무용!I$7) -> 0 | K17: =IF($C17="","",업무용!J$7) -> 0 | L17: =IF($C17="","",업무용!K$7) -> 0 | ... BS17: =IF($C17="","",업무용!BR$7) -> 850
C20: =연료전지!C7 -> 0 | D20: 연료전지 | E20: =IF($C20="","",연료전지!D$7) -> 0 | F20: =IF($C20="","",연료전지!E$7) -> 0 | G20: =IF($C20="","",연료전지!F$7) -> 0 | H20: =IF($C20="","",연료전지!G$7) -> 0 | I20: =IF($C20="","",연료전지!H$7) -> 0 | J20: =IF($C20="","",연료전지!I$7) -> 0 | K20: =IF($C20="","",연료전지!J$7) -> 0 | L20: =IF($C20="","",연료전지!K$7) -> 0 | ... BS20: =IF($C20="","",연료전지!BR$7) -> #DIV/0!
C23: =열병합!C7 -> 0 | D23: 열병합 | E23: =IF($C23="","",열병합!D$7) -> 0 | F23: =IF($C23="","",열병합!E$7) -> 0 | G23: =IF($C23="","",열병합!F$7) -> 0 | H23: =IF($C23="","",열병합!G$7) -> 0 | I23: =IF($C23="","",열병합!H$7) -> 0 | J23: =IF($C23="","",열병합!I$7) -> 0 | K23: =IF($C23="","",열병합!J$7) -> 0 | L23: =IF($C23="","",열병합!K$7) -> 0 | ... BS23: =IF($C23="","",열병합!BR$7) -> #DIV/0!
C26: =열전용설비!C7 -> 0 | D26: 열전용설비 (주택용 外) | E26: =IF($C26="","",열전용설비!D$7) -> 0 | F26: =IF($C26="","",열전용설비!E$7) -> 0 | G26: =IF($C26="","",열전용설비!F$7) -> 0 | H26: =IF($C26="","",열전용설비!G$7) -> 0 | I26: =IF($C26="","",열전용설비!H$7) -> 0 | J26: =IF($C26="","",열전용설비!I$7) -> 0 | K26: =IF($C26="","",열전용설비!J$7) -> 0 | L26: =IF($C26="","",열전용설비!K$7) -> 0 | ... BS26: =IF($C26="","",열전용설비!BR$7) -> #DIV/0!
C29: =영업용!C7 -> 0 | D29: 영업용 | E29: =IF($C29="","",영업용!D$7) -> 0 | F29: =IF($C29="","",영업용!E$7) -> 0 | G29: =IF($C29="","",영업용!F$7) -> 0 | H29: =IF($C29="","",영업용!G$7) -> 0 | I29: =IF($C29="","",영업용!H$7) -> 0 | J29: =IF($C29="","",영업용!I$7) -> 0 | K29: =IF($C29="","",영업용!J$7) -> 0 | L29: =IF($C29="","",영업용!K$7) -> 0 | ... BS29: =IF($C29="","",영업용!BR$7) -> #DIV/0!
C32: =주택용!C7 -> 0 | D32: 주택용 | E32: =IF($C32="","",주택용!D$7) -> 0 | F32: =IF($C32="","",주택용!E$7) -> 0 | G32: =IF($C32="","",주택용!F$7) -> 0 | H32: =IF($C32="","",주택용!G$7) -> 0 | I32: =IF($C32="","",주택용!H$7) -> 0 | J32: =IF($C32="","",주택용!I$7) -> 0 | K32: =IF($C32="","",주택용!J$7) -> 0 | L32: =IF($C32="","",주택용!K$7) -> 0 | ... BQ32: =IF($C32="","",주택용!BP$7) -> -46210408 | BS32: =IF($C32="","",주택용!BR$7) -> 7.1759259 | BU32: 수식확인 | BV32: IF($C32="","",주택용!BQ$7)
C35: =투자보수율가산!C7 -> 1 | D35: 투자보수율가산 | E35: =IF($C35="","",투자보수율가산!D$7) -> 51 | F35: =IF($C35="","",투자보수율가산!E$7) -> 35554000 | G35: =IF($C35="","",투자보수율가산!F$7) -> 0 | H35: =IF($C35="","",투자보수율가산!G$7) -> 35554000 | I35: =IF($C35="","",투자보수율가산!H$7) -> 0 | J35: =IF($C35="","",투자보수율가산!I$7) -> 0 | K35: =IF($C35="","",투자보수율가산!J$7) -> 0 | L35: =IF($C35="","",투자보수율가산!K$7) -> 0 | ... BS35: =IF($C35="","",투자보수율가산!BR$7) -> 0
C38: =투자재원!C7 -> 0 | D38: 배관투자재원 | E38: =IF($C38="","",투자재원!D$7) -> 0 | F38: =IF($C38="","",투자재원!E$7) -> 0 | G38: =IF($C38="","",투자재원!F$7) -> 0 | H38: =IF($C38="","",투자재원!G$7) -> 0 | I38: =IF($C38="","",투자재원!H$7) -> 0 | J38: =IF($C38="","",투자재원!I$7) -> 0 | K38: =IF($C38="","",투자재원!J$7) -> 0 | L38: =IF($C38="","",투자재원!K$7) -> 0 | ... BS38: =IF($C38="","",투자재원!BR$7) -> 0

Sheet 총괄경제
C2: 신규 배관 투자 경제성 분석서(구간별)
D4: 공 사 명 | F4: 투 자 금 액 | I4: 가 정 용 [MJ/(월)] | Q4: 일 반 용 [MJ/(월)] | X4: 산 업 용 [MJ/(월)] | Z4: 연 료 전 지 [MJ/(전,월)] | AB4: 열 병 합 [MJ/(전,월)] | AD4: 열전용설비 (주택용 外) [MJ/(전,월)] | AF4: 수 요 | AG4: 용도별 표준가스 소비량 합계 | AR4: 가 스 소비량 합 계 | AS4: 시 설 분 담 금 | AW4: 기 타 이 익 | AX4: 연 간 판 매 량 [MJ/년] | BJ4: 연 간 | BK4: 연 간 | BL4: 연 간 | BM4: 연 간 | BN4: 경제성분석 | BO4: 경제성분석 | BR4: 비고 (일련 번호)
C5: 용 도 별 | E5: 길이 | F5: 배관투자금액 | G5: 시설투자금액 | H5: 총 투자금액 | I5: 공동주택 전 수 | K5: 단독주택 전 수 | M5: 원 룸 전 수 | O5: 중앙난방 (중집) | Q5: 영업용1 (영업용) | S5: 영업용2 (목욕탕 등) | U5: 업무 난방ㆍ냉방용 | AF5: 전 수 | AG5: 주택용 | AJ5: 주택용 외 | AX5: 가 정 용 | BA5: 일 반 용 | BF5: 산 업 용 | BG5: 연료전지 | BH5: 열 병 합 | BI5: 열전용설비 (주택용 外) | BJ5: 판 매 량 | BK5: 판 매 액 | BL5: 판 매 원 가 | BM5: 판 매 수 익 | BN5: 회수 | BO5: NPV | BP5: IRR | BQ5: 100m
E6: (m) | F6: (원) | I6: 취사 | J6: 난방 | K6: 취사 | L6: 난방 | M6: 취사 | N6: 난방 | O6: 전수 | P6: 판매량 | Q6: 전수 | R6: 판매량 | S6: 전수 | T6: 판매량 | U6: 전수 | V6: 난 방 판매량 | W6: 냉 방 판매량 | X6: 전수 | Y6: 판매량 | Z6: 전수 | AA6: 판매량 | AB6: 전수 | AC6: 판매량 | AD6: 전수 | AE6: 판매량 | AF6: 계 | AG6: 취사 | AH6: 난방 | AI6: 중앙 | AJ6: 영업용1 | AK6: 영업용2 | AL6: 업무난방 | AM6: 냉난 방용 | AN6: 산업용 | AO6: 연료전지 | AP6: 열병합 | AQ6: 열전용설비 (주택용 外) | AS6: 일반 | AT6: 취사전용 | AU6: 수요가부담금 | AV6: 총 시설분담금 | AX6: 취사용 | AY6: 개별난방용 | AZ6: 중앙난방용 (중집용) | BA6: 영업용1 (영업용) | BB6: 영업용2 (목욕탕 등) | BC6: 업무난방용 | BD6: 냉난방용 (난방용) | BE6: 냉난방용 (냉방용) | BJ6: [MJ/년] | BK6: [원/년] | BL6: [원/년] | BM6: [원/년] | BN6: 년수 | BO6: (원) | BP6: (%) | BQ6: 환산 세대수
D7: =COUNTA(A8:A226) -> 2 | E7: =SUM(E8:E226) -> 59 | F7: =SUM(F8:F226) -> 69443000 | G7: =SUM(G8:G226) -> 0 | H7: =SUM(H8:H226) -> 69443000 | I7: =SUM(I8:I226) -> 0 | J7: =SUM(J8:J226) -> 450 | K7: =SUM(K8:K226) -> 0 | L7: =SUM(L8:L226) -> 0 | ... BM7: =SUM(BM8:BM226) -> 32833951 | BO7: =용도별분석!BQ7 -> 3.3639958e+08 | BP7: =용도별분석!BR7 -> 80.658151 | BQ7: =용도별분석!BS7 -> 5962.5
C8: 공공택지 | D8: =IF($A8="","",VLOOKUP($A8,기본데이타!$A$8:$BV$103,COLUMN(기본데이타!F$8),0)) | E8: =IF($A8="","",VLOOKUP($A8,기본데이타!$A$8:$BV$103,COLUMN(기본데이타!G$8),0)) | F8: =IF($A8="","",VLOOKUP($A8,기본데이타!$A$8:$BV$103,COLUMN(기본데이타!H$8),0)) | G8: =IF($A8="","",VLOOKUP($A8,기본데이타!$A$8:$BV$103,COLUMN(기본데이타!I$8),0)) | H8: =IF($A8="","",VLOOKUP($A8,기본데이타!$A$8:$BV$103,COLUMN(기본데이타!J$8),0)) | I8: =IF($A8="","",VLOOKUP($A8,기본데이타!$A$8:$BV$103,COLUMN(기본데이타!K$8),0)) | J8: =IF($A8="","",VLOOKUP($A8,기본데이타!$A$8:$BV$103,COLUMN(기본데이타!L$8),0)) | K8: =IF($A8="","",VLOOKUP($A8,기본데이타!$A$8:$BV$103,COLUMN(기본데이타!M$8),0)) | ... V8: =IF($A8="","",VLOOKUP($A8,기본데이타!$A$8:$BV$103,COLUMN(기본데이타!X$8),0)) | W8: =IF($A8="","",VLOOKUP($A8,기본데이타!$A$8:$BV$103,COLUMN(기본데이타!AA$8),0)) | X8: =IF($A8="","",VLOOKUP($A8,기본데이타!$A$8:$BV$103,COLUMN(기본데이타!AB$8),0)) | Y8: =IF($A8="","",VLOOKUP($A8,기본데이타!$A$8:$BV$103,COLUMN(기본데이타!AC$8),0)) | Z8: =IF($A8="","",VLOOKUP($A8,기본데이타!$A$8:$BV$103,COLUMN(기본데이타!AD$8),0)) | AA8: =IF($A8="","",VLOOKUP($A8,기본데이타!$A$8:$BV$103,COLUMN(기본데이타!AE$8),0)) | AB8: =IF($A8="","",VLOOKUP($A8,기본데이타!$A$8:$BV$103,COLUMN(기본데이타!AF$8),0)) | AC8: =IF($A8="","",VLOOKUP($A8,기본데이타!$A$8:$BV$103,COLUMN(기본데이타!AG$8),0)) | AD8: =IF($A8="","",VLOOKUP($A8,기본데이타!$A$8:$BV$103,COLUMN(기본데이타!AH$8),0)) | ... AU8: =IF($A8="","",VLOOKUP($A8,기본데이타!$A$8:$BV$103,COLUMN(기본데이타!AY$8),0)) | AV8: =IF(AS8="","",SUM(AS8:AU8)) | AW8: =IF($A8="","",VLOOKUP($A8,기본데이타!$A$8:$BV$103,COLUMN(기본데이타!BA$8),0)) | AX8: =IF($A8="","",VLOOKUP($A8,기본데이타!$A$8:$BV$103,COLUMN(기본데이타!BB$8),0)) | AY8: =IF($A8="","",VLOOKUP($A8,기본데이타!$A$8:$BV$103,COLUMN(기본데이타!BC$8),0)) | AZ8: =IF($A8="","",VLOOKUP($A8,기본데이타!$A$8:$BV$103,COLUMN(기본데이타!BD$8),0)) | BA8: =IF($A8="","",VLOOKUP($A8,기본데이타!$A$8:$BV$103,COLUMN(기본데이타!BE$8),0)) | BB8: =IF($A8="","",VLOOKUP($A8,기본데이타!$A$8:$BV$103,COLUMN(기본데이타!BF$8),0)) | BC8: =IF($A8="","",VLOOKUP($A8,기본데이타!$A$8:$BV$103,COLUMN(기본데이타!BG$8),0)) | BD8: =IF($A8="","",VLOOKUP($A8,기본데이타!$A$8:$BV$103,COLUMN(기본데이타!BH$8),0)) | ... BQ8: =IF($A8="","",VLOOKUP($A8,기본데이타!$A$8:$BV$103,COLUMN(기본데이타!BU$8),0)) | BR8: =IF($A8="","",A8)
D9: =IF($A9="","",VLOOKUP($A9,기본데이타!$A$8:$BV$103,COLUMN(기본데이타!F$8),0)) | E9: =IF($A9="","",VLOOKUP($A9,기본데이타!$A$8:$BV$103,COLUMN(기본데이타!G$8),0)) | F9: =IF($A9="","",VLOOKUP($A9,기본데이타!$A$8:$BV$103,COLUMN(기본데이타!H$8),0)) | G9: =IF($A9="","",VLOOKUP($A9,기본데이타!$A$8:$BV$103,COLUMN(기본데이타!I$8),0)) | H9: =IF($A9="","",VLOOKUP($A9,기본데이타!$A$8:$BV$103,COLUMN(기본데이타!J$8),0)) | I9: =IF($A9="","",VLOOKUP($A9,기본데이타!$A$8:$BV$103,COLUMN(기본데이타!K$8),0)) | J9: =IF($A9="","",VLOOKUP($A9,기본데이타!$A$8:$BV$103,COLUMN(기본데이타!L$8),0)) | K9: =IF($A9="","",VLOOKUP($A9,기본데이타!$A$8:$BV$103,COLUMN(기본데이타!M$8),0)) | ... V9: =IF($A9="","",VLOOKUP($A9,기본데이타!$A$8:$BV$103,COLUMN(기본데이타!X$8),0)) | W9: =IF($A9="","",VLOOKUP($A9,기본데이타!$A$8:$BV$103,COLUMN(기본데이타!AA$8),0)) | X9: =IF($A9="","",VLOOKUP($A9,기본데이타!$A$8:$BV$103,COLUMN(기본데이타!AB$8),0)) | Y9: =IF($A9="","",VLOOKUP($A9,기본데이타!$A$8:$BV$103,COLUMN(기본데이타!AC$8),0)) | Z9: =IF($A9="","",VLOOKUP($A9,기본데이타!$A$8:$BV$103,COLUMN(기본데이타!AD$8),0)) | AA9: =IF($A9="","",VLOOKUP($A9,기본데이타!$A$8:$BV$103,COLUMN(기본데이타!AE$8),0)) | AB9: =IF($A9="","",VLOOKUP($A9,기본데이타!$A$8:$BV$103,COLUMN(기본데이타!AF$8),0)) | AC9: =IF($A9="","",VLOOKUP($A9,기본데이타!$A$8:$BV$103,COLUMN(기본데이타!AG$8),0)) | AD9: =IF($A9="","",VLOOKUP($A9,기본데이타!$A$8:$BV$103,COLUMN(기본데이타!AH$8),0)) | ... AU9: =IF($A9="","",VLOOKUP($A9,기본데이타!$A$8:$BV$103,COLUMN(기본데이타!AY$8),0)) | AV9: =IF(AS9="","",SUM(AS9:AU9)) | AW9: =IF($A9="","",VLOOKUP($A9,기본데이타!$A$8:$BV$103,COLUMN(기본데이타!BA$8),0)) | AX9: =IF($A9="","",VLOOKUP($A9,기본데이타!$A$8:$BV$103,COLUMN(기본데이타!BB$8),0)) | AY9: =IF($A9="","",VLOOKUP($A9,기본데이타!$A$8:$BV$103,COLUMN(기본데이타!BC$8),0)) | AZ9: =IF($A9="","",VLOOKUP($A9,기본데이타!$A$8:$BV$103,COLUMN(기본데이타!BD$8),0)) | BA9: =IF($A9="","",VLOOKUP($A9,기본데이타!$A$8:$BV$103,COLUMN(기본데이타!BE$8),0)) | BB9: =IF($A9="","",VLOOKUP($A9,기본데이타!$A$8:$BV$103,COLUMN(기본데이타!BF$8),0)) | BC9: =IF($A9="","",VLOOKUP($A9,기본데이타!$A$8:$BV$103,COLUMN(기본데이타!BG$8),0)) | BD9: =IF($A9="","",VLOOKUP($A9,기본데이타!$A$8:$BV$103,COLUMN(기본데이타!BH$8),0)) | ... BQ9: =IF($A9="","",VLOOKUP($A9,기본데이타!$A$8:$BV$103,COLUMN(기본데이타!BU$8),0)) | BR9: =IF($A9="","",A9)
D10: =IF($A10="","",VLOOKUP($A10,기본데이타!$A$8:$BV$103,COLUMN(기본데이타!F$8),0)) | E10: =IF($A10="","",VLOOKUP($A10,기본데이타!$A$8:$BV$103,COLUMN(기본데이타!G$8),0)) | F10: =IF($A10="","",VLOOKUP($A10,기본데이타!$A$8:$BV$103,COLUMN(기본데이타!H$8),0)) | G10: =IF($A10="","",VLOOKUP($A10,기본데이타!$A$8:$BV$103,COLUMN(기본데이타!I$8),0)) | H10: =IF($A10="","",VLOOKUP($A10,기본데이타!$A$8:$BV$103,COLUMN(기본데이타!J$8),0)) | I10: =IF($A10="","",VLOOKUP($A10,기본데이타!$A$8:$BV$103,COLUMN(기본데이타!K$8),0)) | J10: =IF($A10="","",VLOOKUP($A10,기본데이타!$A$8:$BV$103,COLUMN(기본데이타!L$8),0)) | K10: =IF($A10="","",VLOOKUP($A10,기본데이타!$A$8:$BV$103,COLUMN(기본데이타!M$8),0)) | ... V10: =IF($A10="","",VLOOKUP($A10,기본데이타!$A$8:$BV$103,COLUMN(기본데이타!X$8),0)) | W10: =IF($A10="","",VLOOKUP($A10,기본데이타!$A$8:$BV$103,COLUMN(기본데이타!AA$8),0)) | X10: =IF($A10="","",VLOOKUP($A10,기본데이타!$A$8:$BV$103,COLUMN(기본데이타!AB$8),0)) | Y10: =IF($A10="","",VLOOKUP($A10,기본데이타!$A$8:$BV$103,COLUMN(기본데이타!AC$8),0)) | Z10: =IF($A10="","",VLOOKUP($A10,기본데이타!$A$8:$BV$103,COLUMN(기본데이타!AD$8),0)) | AA10: =IF($A10="","",VLOOKUP($A10,기본데이타!$A$8:$BV$103,COLUMN(기본데이타!AE$8),0)) | AB10: =IF($A10="","",VLOOKUP($A10,기본데이타!$A$8:$BV$103,COLUMN(기본데이타!AF$8),0)) | AC10: =IF($A10="","",VLOOKUP($A10,기본데이타!$A$8:$BV$103,COLUMN(기본데이타!AG$8),0)) | AD10: =IF($A10="","",VLOOKUP($A10,기본데이타!$A$8:$BV$103,COLUMN(기본데이타!AH$8),0)) | ... AU10: =IF($A10="","",VLOOKUP($A10,기본데이타!$A$8:$BV$103,COLUMN(기본데이타!AY$8),0)) | AV10: =IF(AS10="","",SUM(AS10:AU10)) | AW10: =IF($A10="","",VLOOKUP($A10,기본데이타!$A$8:$BV$103,COLUMN(기본데이타!BA$8),0)) | AX10: =IF($A10="","",VLOOKUP($A10,기본데이타!$A$8:$BV$103,COLUMN(기본데이타!BB$8),0)) | AY10: =IF($A10="","",VLOOKUP($A10,기본데이타!$A$8:$BV$103,COLUMN(기본데이타!BC$8),0)) | AZ10: =IF($A10="","",VLOOKUP($A10,기본데이타!$A$8:$BV$103,COLUMN(기본데이타!BD$8),0)) | BA10: =IF($A10="","",VLOOKUP($A10,기본데이타!$A$8:$BV$103,COLUMN(기본데이타!BE$8),0)) | BB10: =IF($A10="","",VLOOKUP($A10,기본데이타!$A$8:$BV$103,COLUMN(기본데이타!BF$8),0)) | BC10: =IF($A10="","",VLOOKUP($A10,기본데이타!$A$8:$BV$103,COLUMN(기본데이타!BG$8),0)) | BD10: =IF($A10="","",VLOOKUP($A10,기본데이타!$A$8:$BV$103,COLUMN(기본데이타!BH$8),0)) | ... BQ10: =IF($A10="","",VLOOKUP($A10,기본데이타!$A$8:$BV$103,COLUMN(기본데이타!BU$8),0)) | BR10: =IF($A10="","",A10)
D11: =IF($A11="","",VLOOKUP($A11,기본데이타!$A$8:$BV$103,COLUMN(기본데이타!F$8),0)) | E11: =IF($A11="","",VLOOKUP($A11,기본데이타!$A$8:$BV$103,COLUMN(기본데이타!G$8),0)) | F11: =IF($A11="","",VLOOKUP($A11,기본데이타!$A$8:$BV$103,COLUMN(기본데이타!H$8),0)) | G11: =IF($A11="","",VLOOKUP($A11,기본데이타!$A$8:$BV$103,COLUMN(기본데이타!I$8),0)) | H11: =IF($A11="","",VLOOKUP($A11,기본데이타!$A$8:$BV$103,COLUMN(기본데이타!J$8),0)) | I11: =IF($A11="","",VLOOKUP($A11,기본데이타!$A$8:$BV$103,COLUMN(기본데이타!K$8),0)) | J11: =IF($A11="","",VLOOKUP($A11,기본데이타!$A$8:$BV$103,COLUMN(기본데이타!L$8),0)) | K11: =IF($A11="","",VLOOKUP($A11,기본데이타!$A$8:$BV$103,COLUMN(기본데이타!M$8),0)) | ... V11: =IF($A11="","",VLOOKUP($A11,기본데이타!$A$8:$BV$103,COLUMN(기본데이타!X$8),0)) | W11: =IF($A11="","",VLOOKUP($A11,기본데이타!$A$8:$BV$103,COLUMN(기본데이타!AA$8),0)) | X11: =IF($A11="","",VLOOKUP($A11,기본데이타!$A$8:$BV$103,COLUMN(기본데이타!AB$8),0)) | Y11: =IF($A11="","",VLOOKUP($A11,기본데이타!$A$8:$BV$103,COLUMN(기본데이타!AC$8),0)) | Z11: =IF($A11="","",VLOOKUP($A11,기본데이타!$A$8:$BV$103,COLUMN(기본데이타!AD$8),0)) | AA11: =IF($A11="","",VLOOKUP($A11,기본데이타!$A$8:$BV$103,COLUMN(기본데이타!AE$8),0)) | AB11: =IF($A11="","",VLOOKUP($A11,기본데이타!$A$8:$BV$103,COLUMN(기본데이타!AF$8),0)) | AC11: =IF($A11="","",VLOOKUP($A11,기본데이타!$A$8:$BV$103,COLUMN(기본데이타!AG$8),0)) | AD11: =IF($A11="","",VLOOKUP($A11,기본데이타!$A$8:$BV$103,COLUMN(기본데이타!AH$8),0)) | ... AU11: =IF($A11="","",VLOOKUP($A11,기본데이타!$A$8:$BV$103,COLUMN(기본데이타!AY$8),0)) | AV11: =IF(AS11="","",SUM(AS11:AU11)) | AW11: =IF($A11="","",VLOOKUP($A11,기본데이타!$A$8:$BV$103,COLUMN(기본데이타!BA$8),0)) | AX11: =IF($A11="","",VLOOKUP($A11,기본데이타!$A$8:$BV$103,COLUMN(기본데이타!BB$8),0)) | AY11: =IF($A11="","",VLOOKUP($A11,기본데이타!$A$8:$BV$103,COLUMN(기본데이타!BC$8),0)) | AZ11: =IF($A11="","",VLOOKUP($A11,기본데이타!$A$8:$BV$103,COLUMN(기본데이타!BD$8),0)) | BA11: =IF($A11="","",VLOOKUP($A11,기본데이타!$A$8:$BV$103,COLUMN(기본데이타!BE$8),0)) | BB11: =IF($A11="","",VLOOKUP($A11,기본데이타!$A$8:$BV$103,COLUMN(기본데이타!BF$8),0)) | BC11: =IF($A11="","",VLOOKUP($A11,기본데이타!$A$8:$BV$103,COLUMN(기본데이타!BG$8),0)) | BD11: =IF($A11="","",VLOOKUP($A11,기본데이타!$A$8:$BV$103,COLUMN(기본데이타!BH$8),0)) | ... BQ11: =IF($A11="","",VLOOKUP($A11,기본데이타!$A$8:$BV$103,COLUMN(기본데이타!BU$8),0)) | BR11: =IF($A11="","",A11)
D12: =IF($A12="","",VLOOKUP($A12,기본데이타!$A$8:$BV$103,COLUMN(기본데이타!F$8),0)) | E12: =IF($A12="","",VLOOKUP($A12,기본데이타!$A$8:$BV$103,COLUMN(기본데이타!G$8),0)) | F12: =IF($A12="","",VLOOKUP($A12,기본데이타!$A$8:$BV$103,COLUMN(기본데이타!H$8),0)) | G12: =IF($A12="","",VLOOKUP($A12,기본데이타!$A$8:$BV$103,COLUMN(기본데이타!I$8),0)) | H12: =IF($A12="","",VLOOKUP($A12,기본데이타!$A$8:$BV$103,COLUMN(기본데이타!J$8),0)) | I12: =IF($A12="","",VLOOKUP($A12,기본데이타!$A$8:$BV$103,COLUMN(기본데이타!K$8),0)) | J12: =IF($A12="","",VLOOKUP($A12,기본데이타!$A$8:$BV$103,COLUMN(기본데이타!L$8),0)) | K12: =IF($A12="","",VLOOKUP($A12,기본데이타!$A$8:$BV$103,COLUMN(기본데이타!M$8),0)) | ... V12: =IF($A12="","",VLOOKUP($A12,기본데이타!$A$8:$BV$103,COLUMN(기본데이타!X$8),0)) | W12: =IF($A12="","",VLOOKUP($A12,기본데이타!$A$8:$BV$103,COLUMN(기본데이타!AA$8),0)) | X12: =IF($A12="","",VLOOKUP($A12,기본데이타!$A$8:$BV$103,COLUMN(기본데이타!AB$8),0)) | Y12: =IF($A12="","",VLOOKUP($A12,기본데이타!$A$8:$BV$103,COLUMN(기본데이타!AC$8),0)) | Z12: =IF($A12="","",VLOOKUP($A12,기본데이타!$A$8:$BV$103,COLUMN(기본데이타!AD$8),0)) | AA12: =IF($A12="","",VLOOKUP($A12,기본데이타!$A$8:$BV$103,COLUMN(기본데이타!AE$8),0)) | AB12: =IF($A12="","",VLOOKUP($A12,기본데이타!$A$8:$BV$103,COLUMN(기본데이타!AF$8),0)) | AC12: =IF($A12="","",VLOOKUP($A12,기본데이타!$A$8:$BV$103,COLUMN(기본데이타!AG$8),0)) | AD12: =IF($A12="","",VLOOKUP($A12,기본데이타!$A$8:$BV$103,COLUMN(기본데이타!AH$8),0)) | ... AU12: =IF($A12="","",VLOOKUP($A12,기본데이타!$A$8:$BV$103,COLUMN(기본데이타!AY$8),0)) | AV12: =IF(AS12="","",SUM(AS12:AU12)) | AW12: =IF($A12="","",VLOOKUP($A12,기본데이타!$A$8:$BV$103,COLUMN(기본데이타!BA$8),0)) | AX12: =IF($A12="","",VLOOKUP($A12,기본데이타!$A$8:$BV$103,COLUMN(기본데이타!BB$8),0)) | AY12: =IF($A12="","",VLOOKUP($A12,기본데이타!$A$8:$BV$103,COLUMN(기본데이타!BC$8),0)) | AZ12: =IF($A12="","",VLOOKUP($A12,기본데이타!$A$8:$BV$103,COLUMN(기본데이타!BD$8),0)) | BA12: =IF($A12="","",VLOOKUP($A12,기본데이타!$A$8:$BV$103,COLUMN(기본데이타!BE$8),0)) | BB12: =IF($A12="","",VLOOKUP($A12,기본데이타!$A$8:$BV$103,COLUMN(기본데이타!BF$8),0)) | BC12: =IF($A12="","",VLOOKUP($A12,기본데이타!$A$8:$BV$103,COLUMN(기본데이타!BG$8),0)) | BD12: =IF($A12="","",VLOOKUP($A12,기본데이타!$A$8:$BV$103,COLUMN(기본데이타!BH$8),0)) | ... BQ12: =IF($A12="","",VLOOKUP($A12,기본데이타!$A$8:$BV$103,COLUMN(기본데이타!BU$8),0)) | BR12: =IF($A12="","",A12)
D13: =IF($A13="","",VLOOKUP($A13,기본데이타!$A$8:$BV$103,COLUMN(기본데이타!F$8),0)) | E13: =IF($A13="","",VLOOKUP($A13,기본데이타!$A$8:$BV$103,COLUMN(기본데이타!G$8),0)) | F13: =IF($A13="","",VLOOKUP($A13,기본데이타!$A$8:$BV$103,COLUMN(기본데이타!H$8),0)) | G13: =IF($A13="","",VLOOKUP($A13,기본데이타!$A$8:$BV$103,COLUMN(기본데이타!I$8),0)) | H13: =IF($A13="","",VLOOKUP($A13,기본데이타!$A$8:$BV$103,COLUMN(기본데이타!J$8),0)) | I13: =IF($A13="","",VLOOKUP($A13,기본데이타!$A$8:$BV$103,COLUMN(기본데이타!K$8),0)) | J13: =IF($A13="","",VLOOKUP($A13,기본데이타!$A$8:$BV$103,COLUMN(기본데이타!L$8),0)) | K13: =IF($A13="","",VLOOKUP($A13,기본데이타!$A$8:$BV$103,COLUMN(기본데이타!M$8),0)) | ... V13: =IF($A13="","",VLOOKUP($A13,기본데이타!$A$8:$BV$103,COLUMN(기본데이타!X$8),0)) | W13: =IF($A13="","",VLOOKUP($A13,기본데이타!$A$8:$BV$103,COLUMN(기본데이타!AA$8),0)) | X13: =IF($A13="","",VLOOKUP($A13,기본데이타!$A$8:$BV$103,COLUMN(기본데이타!AB$8),0)) | Y13: =IF($A13="","",VLOOKUP($A13,기본데이타!$A$8:$BV$103,COLUMN(기본데이타!AC$8),0)) | Z13: =IF($A13="","",VLOOKUP($A13,기본데이타!$A$8:$BV$103,COLUMN(기본데이타!AD$8),0)) | AA13: =IF($A13="","",VLOOKUP($A13,기본데이타!$A$8:$BV$103,COLUMN(기본데이타!AE$8),0)) | AB13: =IF($A13="","",VLOOKUP($A13,기본데이타!$A$8:$BV$103,COLUMN(기본데이타!AF$8),0)) | AC13: =IF($A13="","",VLOOKUP($A13,기본데이타!$A$8:$BV$103,COLUMN(기본데이타!AG$8),0)) | AD13: =IF($A13="","",VLOOKUP($A13,기본데이타!$A$8:$BV$103,COLUMN(기본데이타!AH$8),0)) | ... AU13: =IF($A13="","",VLOOKUP($A13,기본데이타!$A$8:$BV$103,COLUMN(기본데이타!AY$8),0)) | AV13: =IF(AS13="","",SUM(AS13:AU13)) | AW13: =IF($A13="","",VLOOKUP($A13,기본데이타!$A$8:$BV$103,COLUMN(기본데이타!BA$8),0)) | AX13: =IF($A13="","",VLOOKUP($A13,기본데이타!$A$8:$BV$103,COLUMN(기본데이타!BB$8),0)) | AY13: =IF($A13="","",VLOOKUP($A13,기본데이타!$A$8:$BV$103,COLUMN(기본데이타!BC$8),0)) | AZ13: =IF($A13="","",VLOOKUP($A13,기본데이타!$A$8:$BV$103,COLUMN(기본데이타!BD$8),0)) | BA13: =IF($A13="","",VLOOKUP($A13,기본데이타!$A$8:$BV$103,COLUMN(기본데이타!BE$8),0)) | BB13: =IF($A13="","",VLOOKUP($A13,기본데이타!$A$8:$BV$103,COLUMN(기본데이타!BF$8),0)) | BC13: =IF($A13="","",VLOOKUP($A13,기본데이타!$A$8:$BV$103,COLUMN(기본데이타!BG$8),0)) | BD13: =IF($A13="","",VLOOKUP($A13,기본데이타!$A$8:$BV$103,COLUMN(기본데이타!BH$8),0)) | ... BQ13: =IF($A13="","",VLOOKUP($A13,기본데이타!$A$8:$BV$103,COLUMN(기본데이타!BU$8),0)) | BR13: =IF($A13="","",A13)
D14: =IF($A14="","",VLOOKUP($A14,기본데이타!$A$8:$BV$103,COLUMN(기본데이타!F$8),0)) | E14: =IF($A14="","",VLOOKUP($A14,기본데이타!$A$8:$BV$103,COLUMN(기본데이타!G$8),0)) | F14: =IF($A14="","",VLOOKUP($A14,기본데이타!$A$8:$BV$103,COLUMN(기본데이타!H$8),0)) | G14: =IF($A14="","",VLOOKUP($A14,기본데이타!$A$8:$BV$103,COLUMN(기본데이타!I$8),0)) | H14: =IF($A14="","",VLOOKUP($A14,기본데이타!$A$8:$BV$103,COLUMN(기본데이타!J$8),0)) | I14: =IF($A14="","",VLOOKUP($A14,기본데이타!$A$8:$BV$103,COLUMN(기본데이타!K$8),0)) | J14: =IF($A14="","",VLOOKUP($A14,기본데이타!$A$8:$BV$103,COLUMN(기본데이타!L$8),0)) | K14: =IF($A14="","",VLOOKUP($A14,기본데이타!$A$8:$BV$103,COLUMN(기본데이타!M$8),0)) | ... V14: =IF($A14="","",VLOOKUP($A14,기본데이타!$A$8:$BV$103,COLUMN(기본데이타!X$8),0)) | W14: =IF($A14="","",VLOOKUP($A14,기본데이타!$A$8:$BV$103,COLUMN(기본데이타!AA$8),0)) | X14: =IF($A14="","",VLOOKUP($A14,기본데이타!$A$8:$BV$103,COLUMN(기본데이타!AB$8),0)) | Y14: =IF($A14="","",VLOOKUP($A14,기본데이타!$A$8:$BV$103,COLUMN(기본데이타!AC$8),0)) | Z14: =IF($A14="","",VLOOKUP($A14,기본데이타!$A$8:$BV$103,COLUMN(기본데이타!AD$8),0)) | AA14: =IF($A14="","",VLOOKUP($A14,기본데이타!$A$8:$BV$103,COLUMN(기본데이타!AE$8),0)) | AB14: =IF($A14="","",VLOOKUP($A14,기본데이타!$A$8:$BV$103,COLUMN(기본데이타!AF$8),0)) | AC14: =IF($A14="","",VLOOKUP($A14,기본데이타!$A$8:$BV$103,COLUMN(기본데이타!AG$8),0)) | AD14: =IF($A14="","",VLOOKUP($A14,기본데이타!$A$8:$BV$103,COLUMN(기본데이타!AH$8),0)) | ... AU14: =IF($A14="","",VLOOKUP($A14,기본데이타!$A$8:$BV$103,COLUMN(기본데이타!AY$8),0)) | AV14: =IF(AS14="","",SUM(AS14:AU14)) | AW14: =IF($A14="","",VLOOKUP($A14,기본데이타!$A$8:$BV$103,COLUMN(기본데이타!BA$8),0)) | AX14: =IF($A14="","",VLOOKUP($A14,기본데이타!$A$8:$BV$103,COLUMN(기본데이타!BB$8),0)) | AY14: =IF($A14="","",VLOOKUP($A14,기본데이타!$A$8:$BV$103,COLUMN(기본데이타!BC$8),0)) | AZ14: =IF($A14="","",VLOOKUP($A14,기본데이타!$A$8:$BV$103,COLUMN(기본데이타!BD$8),0)) | BA14: =IF($A14="","",VLOOKUP($A14,기본데이타!$A$8:$BV$103,COLUMN(기본데이타!BE$8),0)) | BB14: =IF($A14="","",VLOOKUP($A14,기본데이타!$A$8:$BV$103,COLUMN(기본데이타!BF$8),0)) | BC14: =IF($A14="","",VLOOKUP($A14,기본데이타!$A$8:$BV$103,COLUMN(기본데이타!BG$8),0)) | BD14: =IF($A14="","",VLOOKUP($A14,기본데이타!$A$8:$BV$103,COLUMN(기본데이타!BH$8),0)) | ... BQ14: =IF($A14="","",VLOOKUP($A14,기본데이타!$A$8:$BV$103,COLUMN(기본데이타!BU$8),0)) | BR14: =IF($A14="","",A14)
D15: =IF($A15="","",VLOOKUP($A15,기본데이타!$A$8:$BV$103,COLUMN(기본데이타!F$8),0)) | E15: =IF($A15="","",VLOOKUP($A15,기본데이타!$A$8:$BV$103,COLUMN(기본데이타!G$8),0)) | F15: =IF($A15="","",VLOOKUP($A15,기본데이타!$A$8:$BV$103,COLUMN(기본데이타!H$8),0)) | G15: =IF($A15="","",VLOOKUP($A15,기본데이타!$A$8:$BV$103,COLUMN(기본데이타!I$8),0)) | H15: =IF($A15="","",VLOOKUP($A15,기본데이타!$A$8:$BV$103,COLUMN(기본데이타!J$8),0)) | I15: =IF($A15="","",VLOOKUP($A15,기본데이타!$A$8:$BV$103,COLUMN(기본데이타!K$8),0)) | J15: =IF($A15="","",VLOOKUP($A15,기본데이타!$A$8:$BV$103,COLUMN(기본데이타!L$8),0)) | K15: =IF($A15="","",VLOOKUP($A15,기본데이타!$A$8:$BV$103,COLUMN(기본데이타!M$8),0)) | ... V15: =IF($A15="","",VLOOKUP($A15,기본데이타!$A$8:$BV$103,COLUMN(기본데이타!X$8),0)) | W15: =IF($A15="","",VLOOKUP($A15,기본데이타!$A$8:$BV$103,COLUMN(기본데이타!AA$8),0)) | X15: =IF($A15="","",VLOOKUP($A15,기본데이타!$A$8:$BV$103,COLUMN(기본데이타!AB$8),0)) | Y15: =IF($A15="","",VLOOKUP($A15,기본데이타!$A$8:$BV$103,COLUMN(기본데이타!AC$8),0)) | Z15: =IF($A15="","",VLOOKUP($A15,기본데이타!$A$8:$BV$103,COLUMN(기본데이타!AD$8),0)) | AA15: =IF($A15="","",VLOOKUP($A15,기본데이타!$A$8:$BV$103,COLUMN(기본데이타!AE$8),0)) | AB15: =IF($A15="","",VLOOKUP($A15,기본데이타!$A$8:$BV$103,COLUMN(기본데이타!AF$8),0)) | AC15: =IF($A15="","",VLOOKUP($A15,기본데이타!$A$8:$BV$103,COLUMN(기본데이타!AG$8),0)) | AD15: =IF($A15="","",VLOOKUP($A15,기본데이타!$A$8:$BV$103,COLUMN(기본데이타!AH$8),0)) | ... AU15: =IF($A15="","",VLOOKUP($A15,기본데이타!$A$8:$BV$103,COLUMN(기본데이타!AY$8),0)) | AV15: =IF(AS15="","",SUM(AS15:AU15)) | AW15: =IF($A15="","",VLOOKUP($A15,기본데이타!$A$8:$BV$103,COLUMN(기본데이타!BA$8),0)) | AX15: =IF($A15="","",VLOOKUP($A15,기본데이타!$A$8:$BV$103,COLUMN(기본데이타!BB$8),0)) | AY15: =IF($A15="","",VLOOKUP($A15,기본데이타!$A$8:$BV$103,COLUMN(기본데이타!BC$8),0)) | AZ15: =IF($A15="","",VLOOKUP($A15,기본데이타!$A$8:$BV$103,COLUMN(기본데이타!BD$8),0)) | BA15: =IF($A15="","",VLOOKUP($A15,기본데이타!$A$8:$BV$103,COLUMN(기본데이타!BE$8),0)) | BB15: =IF($A15="","",VLOOKUP($A15,기본데이타!$A$8:$BV$103,COLUMN(기본데이타!BF$8),0)) | BC15: =IF($A15="","",VLOOKUP($A15,기본데이타!$A$8:$BV$103,COLUMN(기본데이타!BG$8),0)) | BD15: =IF($A15="","",VLOOKUP($A15,기본데이타!$A$8:$BV$103,COLUMN(기본데이타!BH$8),0)) | ... BQ15: =IF($A15="","",VLOOKUP($A15,기본데이타!$A$8:$BV$103,COLUMN(기본데이타!BU$8),0)) | BR15: =IF($A15="","",A15)
D16: =IF($A16="","",VLOOKUP($A16,기본데이타!$A$8:$BV$103,COLUMN(기본데이타!F$8),0)) | E16: =IF($A16="","",VLOOKUP($A16,기본데이타!$A$8:$BV$103,COLUMN(기본데이타!G$8),0)) | F16: =IF($A16="","",VLOOKUP($A16,기본데이타!$A$8:$BV$103,COLUMN(기본데이타!H$8),0)) | G16: =IF($A16="","",VLOOKUP($A16,기본데이타!$A$8:$BV$103,COLUMN(기본데이타!I$8),0)) | H16: =IF($A16="","",VLOOKUP($A16,기본데이타!$A$8:$BV$103,COLUMN(기본데이타!J$8),0)) | I16: =IF($A16="","",VLOOKUP($A16,기본데이타!$A$8:$BV$103,COLUMN(기본데이타!K$8),0)) | J16: =IF($A16="","",VLOOKUP($A16,기본데이타!$A$8:$BV$103,COLUMN(기본데이타!L$8),0)) | K16: =IF($A16="","",VLOOKUP($A16,기본데이타!$A$8:$BV$103,COLUMN(기본데이타!M$8),0)) | ... V16: =IF($A16="","",VLOOKUP($A16,기본데이타!$A$8:$BV$103,COLUMN(기본데이타!X$8),0)) | W16: =IF($A16="","",VLOOKUP($A16,기본데이타!$A$8:$BV$103,COLUMN(기본데이타!AA$8),0)) | X16: =IF($A16="","",VLOOKUP($A16,기본데이타!$A$8:$BV$103,COLUMN(기본데이타!AB$8),0)) | Y16: =IF($A16="","",VLOOKUP($A16,기본데이타!$A$8:$BV$103,COLUMN(기본데이타!AC$8),0)) | Z16: =IF($A16="","",VLOOKUP($A16,기본데이타!$A$8:$BV$103,COLUMN(기본데이타!AD$8),0)) | AA16: =IF($A16="","",VLOOKUP($A16,기본데이타!$A$8:$BV$103,COLUMN(기본데이타!AE$8),0)) | AB16: =IF($A16="","",VLOOKUP($A16,기본데이타!$A$8:$BV$103,COLUMN(기본데이타!AF$8),0)) | AC16: =IF($A16="","",VLOOKUP($A16,기본데이타!$A$8:$BV$103,COLUMN(기본데이타!AG$8),0)) | AD16: =IF($A16="","",VLOOKUP($A16,기본데이타!$A$8:$BV$103,COLUMN(기본데이타!AH$8),0)) | ... AU16: =IF($A16="","",VLOOKUP($A16,기본데이타!$A$8:$BV$103,COLUMN(기본데이타!AY$8),0)) | AV16: =IF(AS16="","",SUM(AS16:AU16)) | AW16: =IF($A16="","",VLOOKUP($A16,기본데이타!$A$8:$BV$103,COLUMN(기본데이타!BA$8),0)) | AX16: =IF($A16="","",VLOOKUP($A16,기본데이타!$A$8:$BV$103,COLUMN(기본데이타!BB$8),0)) | AY16: =IF($A16="","",VLOOKUP($A16,기본데이타!$A$8:$BV$103,COLUMN(기본데이타!BC$8),0)) | AZ16: =IF($A16="","",VLOOKUP($A16,기본데이타!$A$8:$BV$103,COLUMN(기본데이타!BD$8),0)) | BA16: =IF($A16="","",VLOOKUP($A16,기본데이타!$A$8:$BV$103,COLUMN(기본데이타!BE$8),0)) | BB16: =IF($A16="","",VLOOKUP($A16,기본데이타!$A$8:$BV$103,COLUMN(기본데이타!BF$8),0)) | BC16: =IF($A16="","",VLOOKUP($A16,기본데이타!$A$8:$BV$103,COLUMN(기본데이타!BG$8),0)) | BD16: =IF($A16="","",VLOOKUP($A16,기본데이타!$A$8:$BV$103,COLUMN(기본데이타!BH$8),0)) | ... BQ16: =IF($A16="","",VLOOKUP($A16,기본데이타!$A$8:$BV$103,COLUMN(기본데이타!BU$8),0)) | BR16: =IF($A16="","",A16)
D17: =IF($A17="","",VLOOKUP($A17,기본데이타!$A$8:$BV$103,COLUMN(기본데이타!F$8),0)) | E17: =IF($A17="","",VLOOKUP($A17,기본데이타!$A$8:$BV$103,COLUMN(기본데이타!G$8),0)) | F17: =IF($A17="","",VLOOKUP($A17,기본데이타!$A$8:$BV$103,COLUMN(기본데이타!H$8),0)) | G17: =IF($A17="","",VLOOKUP($A17,기본데이타!$A$8:$BV$103,COLUMN(기본데이타!I$8),0)) | H17: =IF($A17="","",VLOOKUP($A17,기본데이타!$A$8:$BV$103,COLUMN(기본데이타!J$8),0)) | I17: =IF($A17="","",VLOOKUP($A17,기본데이타!$A$8:$BV$103,COLUMN(기본데이타!K$8),0)) | J17: =IF($A17="","",VLOOKUP($A17,기본데이타!$A$8:$BV$103,COLUMN(기본데이타!L$8),0)) | K17: =IF($A17="","",VLOOKUP($A17,기본데이타!$A$8:$BV$103,COLUMN(기본데이타!M$8),0)) | ... V17: =IF($A17="","",VLOOKUP($A17,기본데이타!$A$8:$BV$103,COLUMN(기본데이타!X$8),0)) | W17: =IF($A17="","",VLOOKUP($A17,기본데이타!$A$8:$BV$103,COLUMN(기본데이타!AA$8),0)) | X17: =IF($A17="","",VLOOKUP($A17,기본데이타!$A$8:$BV$103,COLUMN(기본데이타!AB$8),0)) | Y17: =IF($A17="","",VLOOKUP($A17,기본데이타!$A$8:$BV$103,COLUMN(기본데이타!AC$8),0)) | Z17: =IF($A17="","",VLOOKUP($A17,기본데이타!$A$8:$BV$103,COLUMN(기본데이타!AD$8),0)) | AA17: =IF($A17="","",VLOOKUP($A17,기본데이타!$A$8:$BV$103,COLUMN(기본데이타!AE$8),0)) | AB17: =IF($A17="","",VLOOKUP($A17,기본데이타!$A$8:$BV$103,COLUMN(기본데이타!AF$8),0)) | AC17: =IF($A17="","",VLOOKUP($A17,기본데이타!$A$8:$BV$103,COLUMN(기본데이타!AG$8),0)) | AD17: =IF($A17="","",VLOOKUP($A17,기본데이타!$A$8:$BV$103,COLUMN(기본데이타!AH$8),0)) | ... AU17: =IF($A17="","",VLOOKUP($A17,기본데이타!$A$8:$BV$103,COLUMN(기본데이타!AY$8),0)) | AV17: =IF(AS17="","",SUM(AS17:AU17)) | AW17: =IF($A17="","",VLOOKUP($A17,기본데이타!$A$8:$BV$103,COLUMN(기본데이타!BA$8),0)) | AX17: =IF($A17="","",VLOOKUP($A17,기본데이타!$A$8:$BV$103,COLUMN(기본데이타!BB$8),0)) | AY17: =IF($A17="","",VLOOKUP($A17,기본데이타!$A$8:$BV$103,COLUMN(기본데이타!BC$8),0)) | AZ17: =IF($A17="","",VLOOKUP($A17,기본데이타!$A$8:$BV$103,COLUMN(기본데이타!BD$8),0)) | BA17: =IF($A17="","",VLOOKUP($A17,기본데이타!$A$8:$BV$103,COLUMN(기본데이타!BE$8),0)) | BB17: =IF($A17="","",VLOOKUP($A17,기본데이타!$A$8:$BV$103,COLUMN(기본데이타!BF$8),0)) | BC17: =IF($A17="","",VLOOKUP($A17,기본데이타!$A$8:$BV$103,COLUMN(기본데이타!BG$8),0)) | BD17: =IF($A17="","",VLOOKUP($A17,기본데이타!$A$8:$BV$103,COLUMN(기본데이타!BH$8),0)) | ... BQ17: =IF($A17="","",VLOOKUP($A17,기본데이타!$A$8:$BV$103,COLUMN(기본데이타!BU$8),0)) | BR17: =IF($A17="","",A17)
D18: =IF($A18="","",VLOOKUP($A18,기본데이타!$A$8:$BV$103,COLUMN(기본데이타!F$8),0)) | E18: =IF($A18="","",VLOOKUP($A18,기본데이타!$A$8:$BV$103,COLUMN(기본데이타!G$8),0)) | F18: =IF($A18="","",VLOOKUP($A18,기본데이타!$A$8:$BV$103,COLUMN(기본데이타!H$8),0)) | G18: =IF($A18="","",VLOOKUP($A18,기본데이타!$A$8:$BV$103,COLUMN(기본데이타!I$8),0)) | H18: =IF($A18="","",VLOOKUP($A18,기본데이타!$A$8:$BV$103,COLUMN(기본데이타!J$8),0)) | I18: =IF($A18="","",VLOOKUP($A18,기본데이타!$A$8:$BV$103,COLUMN(기본데이타!K$8),0)) | J18: =IF($A18="","",VLOOKUP($A18,기본데이타!$A$8:$BV$103,COLUMN(기본데이타!L$8),0)) | K18: =IF($A18="","",VLOOKUP($A18,기본데이타!$A$8:$BV$103,COLUMN(기본데이타!M$8),0)) | ... V18: =IF($A18="","",VLOOKUP($A18,기본데이타!$A$8:$BV$103,COLUMN(기본데이타!X$8),0)) | W18: =IF($A18="","",VLOOKUP($A18,기본데이타!$A$8:$BV$103,COLUMN(기본데이타!AA$8),0)) | X18: =IF($A18="","",VLOOKUP($A18,기본데이타!$A$8:$BV$103,COLUMN(기본데이타!AB$8),0)) | Y18: =IF($A18="","",VLOOKUP($A18,기본데이타!$A$8:$BV$103,COLUMN(기본데이타!AC$8),0)) | Z18: =IF($A18="","",VLOOKUP($A18,기본데이타!$A$8:$BV$103,COLUMN(기본데이타!AD$8),0)) | AA18: =IF($A18="","",VLOOKUP($A18,기본데이타!$A$8:$BV$103,COLUMN(기본데이타!AE$8),0)) | AB18: =IF($A18="","",VLOOKUP($A18,기본데이타!$A$8:$BV$103,COLUMN(기본데이타!AF$8),0)) | AC18: =IF($A18="","",VLOOKUP($A18,기본데이타!$A$8:$BV$103,COLUMN(기본데이타!AG$8),0)) | AD18: =IF($A18="","",VLOOKUP($A18,기본데이타!$A$8:$BV$103,COLUMN(기본데이타!AH$8),0)) | ... AU18: =IF($A18="","",VLOOKUP($A18,기본데이타!$A$8:$BV$103,COLUMN(기본데이타!AY$8),0)) | AV18: =IF(AS18="","",SUM(AS18:AU18)) | AW18: =IF($A18="","",VLOOKUP($A18,기본데이타!$A$8:$BV$103,COLUMN(기본데이타!BA$8),0)) | AX18: =IF($A18="","",VLOOKUP($A18,기본데이타!$A$8:$BV$103,COLUMN(기본데이타!BB$8),0)) | AY18: =IF($A18="","",VLOOKUP($A18,기본데이타!$A$8:$BV$103,COLUMN(기본데이타!BC$8),0)) | AZ18: =IF($A18="","",VLOOKUP($A18,기본데이타!$A$8:$BV$103,COLUMN(기본데이타!BD$8),0)) | BA18: =IF($A18="","",VLOOKUP($A18,기본데이타!$A$8:$BV$103,COLUMN(기본데이타!BE$8),0)) | BB18: =IF($A18="","",VLOOKUP($A18,기본데이타!$A$8:$BV$103,COLUMN(기본데이타!BF$8),0)) | BC18: =IF($A18="","",VLOOKUP($A18,기본데이타!$A$8:$BV$103,COLUMN(기본데이타!BG$8),0)) | BD18: =IF($A18="","",VLOOKUP($A18,기본데이타!$A$8:$BV$103,COLUMN(기본데이타!BH$8),0)) | ... BQ18: =IF($A18="","",VLOOKUP($A18,기본데이타!$A$8:$BV$103,COLUMN(기본데이타!BU$8),0)) | BR18: =IF($A18="","",A18)
